Workbook

Sheet Home
C1: TRADING SECRETS ACADEMY PVT LTD | J1: NIFTY WEEKLY OPTIONS CONTROL CENTER
C2: Quality, Trust, Consistency & Ethics
C3: NIFTY WEEKLY OPTION SELLING — PROFESSIONAL TRADING WORKBOOK
A4: Licence Number: TSA-MURU-2419 | Name: MURUGAN M | Mail ID: muruganm56789@gmail.com | Contact Number: 8610022419
A6: CALCULATION | E6: ORDERS | I6: TRACKING
A10: PORTFOLIO OVERVIEW
A11: Capital Used | C11: Total P/L | E11: Overall Return | G11: Completed | I11: Winning Trades | K11: Open Trades
A12: ='NIFTY Tracking'!B8 -> 320000 | C12: ='NIFTY Tracking'!$K$6 -> 49593.863 | E12: ='NIFTY Tracking'!$K$7 -> 0.15498082 | G12: ='NIFTY Tracking'!$K$8 -> 11 | I12: ='NIFTY Tracking'!$O$6 -> 7 | K12: ='NIFTY Tracking'!$K$9 -> 1
A16: CURRENT CALCULATION & ORDER STATUS
A17: Side | C17: Final Strike | E17: Expiry | G17: Selected Setup | I17: Holding Status | K17: Readiness
A18: CALL Sell | C18: =IF('NIFTY Calculation'!$B$40="","INPUT REQUIRED",'NIFTY Calculation'!$B$40) -> 23300 | E18: =IF('NIFTY Calculation'!$C$40="","",'NIFTY Calculation'!$C$40) -> 46287 | G18: =IF('NIFTY Orders'!$B$10="Call Sell Holding","Latest Tracking CALL",IF('NIFTY Orders'!$B$21="","",'NIFTY Orders'!$B$21)) -> Normal CALL | I18: ='NIFTY Orders'!$C$21 -> No Holding | K18: ='NIFTY Orders'!$I$21 -> READY
A19: PUT Sell | C19: =IF('NIFTY Calculation'!$J$40="","INPUT REQUIRED",'NIFTY Calculation'!$J$40) -> 23300 | E19: =IF('NIFTY Calculation'!$K$40="","",'NIFTY Calculation'!$K$40) -> 46287 | G19: =IF('NIFTY Orders'!$J$10="Put Sell Holding","Latest Tracking PUT",IF('NIFTY Orders'!$B$22="","",'NIFTY Orders'!$B$22)) -> Normal PUT | I19: ='NIFTY Orders'!$C$22 -> No Holding | K19: ='NIFTY Orders'!$I$22 -> READY
A21: DAILY WORKFLOW | H21: INPUT COLOUR GUIDE
A22: 1 | B22: Enter trading date, expiry day and three-day spot data | H22: Dropdown | J22: Dark blue — choose from list
A23: 2 | B23: Enter premium and OI values for the strike screens | H23: Manual Input | J23: Pale yellow — type or paste
A24: 3 | B24: Select eligible normal or gap strikes and complete premium data | H24: Automatic | J24: Blue-grey / grey — formula
A25: 4 | B25: Choose the setup and holding status in NIFTY Orders | H25: Warning | J25: Amber / red — review required
A26: 5 | B26: Place only tickets showing YES after reviewing missed checks
A27: 6 | B27: Record the completed or open trade in NIFTY Tracking | H27: RISK NOTICE Trading derivatives involves substantial risk. Verify strikes, expiry, quantity and broker order details before execution. The workbook calculates method levels but cannot confirm fills, slippage, margin availability or exchange conditions.
A29: SOURCE & VERSION Trading method migrated from 2DAY_Nifty_Weekly_Option_Selling.xlsx. Visual system follows the approved MCX Gold and Silver professional workbooks. Version 1.0 — 2026-09-18.
C35: TRADING SECRETS ACADEMY PVT LTD | Quality, Trust, Consistency & Ethics
C36: Office Support: Mrs. Sathyavani +91 90425 87730 | Mrs. Suganya +91 80569 25382
C37: Calculations & Live Market Support: Mr. Vanaraja +91 72005 75175 | Mr. Gokul +91 72005 75154
C38: Registered: Sivaganga 630611 | Head Office: West Tambaram, Chennai 600045

Sheet NIFTY Calculation
C1: TRADING SECRETS ACADEMY PVT LTD | M1: NIFTY WEEKLY OPTIONS 3DHH / 3DLL
C2: Quality, Trust, Consistency & Ethics
C3: CALCULATION & TRADING LEVELS
A4: Licence Number: TSA-MURU-2419 | Name: MURUGAN M | Mail ID: muruganm56789@gmail.com | Contact Number: 8610022419
A5: WORKFLOW: enter daily inputs → review eligibility → select an eligible strike → confirm final levels → open Orders
A6: TRADING DATE, EXPIRY & THREE-DAY SPOT DATA
A7: Trading Date | B7: 46286 | H7: 3DHH | I7: =IF(COUNT(E9:E11)<3,"",MAX(E9:E11)) -> 23592.85 | K7: PUT End Strike | L7: =IF(I9="","",CEILING(I9,Settings!$B$12)) -> 23650
A8: Expiry Day | B8: Tuesday | E8: High | F8: Low | H8: 3DLL | I8: =IF(COUNT(F9:F11)<3,"",MIN(F9:F11)) -> 23118.6 | K8: PUT Start Strike | L8: =IF(L7="","",L7-(Settings!$B$13-1)*Settings!$B$12) -> 23200
A9: Days Until Expiry | B9: =IF(OR(B7="",B8=""),"",MOD(MATCH(B8,Settings!$F$7:$F$11,0)-WEEKDAY(B7,2),7)) -> 1 | D9: Day 01 | E9: 23448.1 | F9: 23448.1 | H9: Upper Strike Factor | I9: =IF(I7="","",MROUND(I7*(1+Settings!$B$11),Settings!$B$19)) -> 23628.2 | K9: CALL End Strike | L9: =IF(I10="","",FLOOR(I10,Settings!$B$12)) -> 23050
A10: Contract Suggestion | B10: =IF(B9="","",IF(B9<=Settings!$B$21,"NEXT WEEK EXPIRY","CURRENT WEEK EXPIRY")) -> NEXT WEEK EXPIRY | D10: Day 02 | E10: 23592.85 | F10: 23118.6 | H10: Lower Strike Factor | I10: =IF(I8="","",MROUND(I8*(1-Settings!$B$11),Settings!$B$19)) -> 23083.9 | K10: CALL Start Strike | L10: =IF(L9="","",L9+(Settings!$B$13-1)*Settings!$B$12) -> 23500
D11: Day 03 | E11: 23448.1 | F11: 23448.1
A12: NORMAL STRIKE SCREENING
A13: NORMAL CALL SELL | I13: NORMAL PUT SELL
A14: No. | B14: Strike | C14: Required Premium | D14: 3DLL Premium | E14: Premium Status | F14: Current OI | G14: OI Status | H14: Final Status | I14: No. | J14: Strike | K14: Required Premium | L14: 3DLL Premium | M14: Premium Status | N14: Current OI | O14: OI Status | P14: Final Status
A15: 1 | B15: =IF($L$10="","",$L$10-(A15-1)*Settings!$B$12) -> 23500 | C15: =IF(B15="","",MROUND(B15*Settings!$B$7,Settings!$B$18)) -> 211.5 | E15: =IF(D15="","",IF(D15>=C15,"Eligible","Not Eligible")) | G15: =IF(F15="","",IF(F15>=Settings!$B$10,"Eligible","Not Eligible")) | H15: =IF(OR(E15="",G15=""),"",IF(AND(E15="Eligible",G15="Eligible"),"Eligible","Not Eligible")) | I15: 1 | J15: =IF($L$8="","",$L$8+(I15-1)*Settings!$B$12) -> 23200 | K15: =IF(J15="","",MROUND(J15*Settings!$B$7,Settings!$B$18)) -> 208.8 | M15: =IF(L15="","",IF(L15>=K15,"Eligible","Not Eligible")) | O15: =IF(N15="","",IF(N15>=Settings!$B$10,"Eligible","Not Eligible")) | P15: =IF(OR(M15="",O15=""),"",IF(AND(M15="Eligible",O15="Eligible"),"Eligible","Not Eligible"))
A16: 2 | B16: =IF($L$10="","",$L$10-(A16-1)*Settings!$B$12) -> 23450 | C16: =IF(B16="","",MROUND(B16*Settings!$B$7,Settings!$B$18)) -> 211.05 | E16: =IF(D16="","",IF(D16>=C16,"Eligible","Not Eligible")) | F16: 35000 | G16: =IF(F16="","",IF(F16>=Settings!$B$10,"Eligible","Not Eligible")) -> Eligible | H16: =IF(OR(E16="",G16=""),"",IF(AND(E16="Eligible",G16="Eligible"),"Eligible","Not Eligible")) | I16: 2 | J16: =IF($L$8="","",$L$8+(I16-1)*Settings!$B$12) -> 23250 | K16: =IF(J16="","",MROUND(J16*Settings!$B$7,Settings!$B$18)) -> 209.25 | M16: =IF(L16="","",IF(L16>=K16,"Eligible","Not Eligible")) | O16: =IF(N16="","",IF(N16>=Settings!$B$10,"Eligible","Not Eligible")) | P16: =IF(OR(M16="",O16=""),"",IF(AND(M16="Eligible",O16="Eligible"),"Eligible","Not Eligible"))
A17: 3 | B17: =IF($L$10="","",$L$10-(A17-1)*Settings!$B$12) -> 23400 | C17: =IF(B17="","",MROUND(B17*Settings!$B$7,Settings!$B$18)) -> 210.6 | E17: =IF(D17="","",IF(D17>=C17,"Eligible","Not Eligible")) | G17: =IF(F17="","",IF(F17>=Settings!$B$10,"Eligible","Not Eligible")) | H17: =IF(OR(E17="",G17=""),"",IF(AND(E17="Eligible",G17="Eligible"),"Eligible","Not Eligible")) | I17: 3 | J17: =IF($L$8="","",$L$8+(I17-1)*Settings!$B$12) -> 23300 | K17: =IF(J17="","",MROUND(J17*Settings!$B$7,Settings!$B$18)) -> 209.7 | M17: =IF(L17="","",IF(L17>=K17,"Eligible","Not Eligible")) | N17: 45000 | O17: =IF(N17="","",IF(N17>=Settings!$B$10,"Eligible","Not Eligible")) -> Eligible | P17: =IF(OR(M17="",O17=""),"",IF(AND(M17="Eligible",O17="Eligible"),"Eligible","Not Eligible"))
A18: 4 | B18: =IF($L$10="","",$L$10-(A18-1)*Settings!$B$12) -> 23350 | C18: =IF(B18="","",MROUND(B18*Settings!$B$7,Settings!$B$18)) -> 210.15 | E18: =IF(D18="","",IF(D18>=C18,"Eligible","Not Eligible")) | G18: =IF(F18="","",IF(F18>=Settings!$B$10,"Eligible","Not Eligible")) | H18: =IF(OR(E18="",G18=""),"",IF(AND(E18="Eligible",G18="Eligible"),"Eligible","Not Eligible")) | I18: 4 | J18: =IF($L$8="","",$L$8+(I18-1)*Settings!$B$12) -> 23350 | K18: =IF(J18="","",MROUND(J18*Settings!$B$7,Settings!$B$18)) -> 210.15 | M18: =IF(L18="","",IF(L18>=K18,"Eligible","Not Eligible")) | O18: =IF(N18="","",IF(N18>=Settings!$B$10,"Eligible","Not Eligible")) | P18: =IF(OR(M18="",O18=""),"",IF(AND(M18="Eligible",O18="Eligible"),"Eligible","Not Eligible"))
A19: 5 | B19: =IF($L$10="","",$L$10-(A19-1)*Settings!$B$12) -> 23300 | C19: =IF(B19="","",MROUND(B19*Settings!$B$7,Settings!$B$18)) -> 209.7 | E19: =IF(D19="","",IF(D19>=C19,"Eligible","Not Eligible")) | G19: =IF(F19="","",IF(F19>=Settings!$B$10,"Eligible","Not Eligible")) | H19: =IF(OR(E19="",G19=""),"",IF(AND(E19="Eligible",G19="Eligible"),"Eligible","Not Eligible")) | I19: 5 | J19: =IF($L$8="","",$L$8+(I19-1)*Settings!$B$12) -> 23400 | K19: =IF(J19="","",MROUND(J19*Settings!$B$7,Settings!$B$18)) -> 210.6 | M19: =IF(L19="","",IF(L19>=K19,"Eligible","Not Eligible")) | O19: =IF(N19="","",IF(N19>=Settings!$B$10,"Eligible","Not Eligible")) | P19: =IF(OR(M19="",O19=""),"",IF(AND(M19="Eligible",O19="Eligible"),"Eligible","Not Eligible"))
A20: 6 | B20: =IF($L$10="","",$L$10-(A20-1)*Settings!$B$12) -> 23250 | C20: =IF(B20="","",MROUND(B20*Settings!$B$7,Settings!$B$18)) -> 209.25 | E20: =IF(D20="","",IF(D20>=C20,"Eligible","Not Eligible")) | G20: =IF(F20="","",IF(F20>=Settings!$B$10,"Eligible","Not Eligible")) | H20: =IF(OR(E20="",G20=""),"",IF(AND(E20="Eligible",G20="Eligible"),"Eligible","Not Eligible")) | I20: 6 | J20: =IF($L$8="","",$L$8+(I20-1)*Settings!$B$12) -> 23450 | K20: =IF(J20="","",MROUND(J20*Settings!$B$7,Settings!$B$18)) -> 211.05 | M20: =IF(L20="","",IF(L20>=K20,"Eligible","Not Eligible")) | O20: =IF(N20="","",IF(N20>=Settings!$B$10,"Eligible","Not Eligible")) | P20: =IF(OR(M20="",O20=""),"",IF(AND(M20="Eligible",O20="Eligible"),"Eligible","Not Eligible"))
A21: 7 | B21: =IF($L$10="","",$L$10-(A21-1)*Settings!$B$12) -> 23200 | C21: =IF(B21="","",MROUND(B21*Settings!$B$7,Settings!$B$18)) -> 208.8 | E21: =IF(D21="","",IF(D21>=C21,"Eligible","Not Eligible")) | G21: =IF(F21="","",IF(F21>=Settings!$B$10,"Eligible","Not Eligible")) | H21: =IF(OR(E21="",G21=""),"",IF(AND(E21="Eligible",G21="Eligible"),"Eligible","Not Eligible")) | I21: 7 | J21: =IF($L$8="","",$L$8+(I21-1)*Settings!$B$12) -> 23500 | K21: =IF(J21="","",MROUND(J21*Settings!$B$7,Settings!$B$18)) -> 211.5 | M21: =IF(L21="","",IF(L21>=K21,"Eligible","Not Eligible")) | O21: =IF(N21="","",IF(N21>=Settings!$B$10,"Eligible","Not Eligible")) | P21: =IF(OR(M21="",O21=""),"",IF(AND(M21="Eligible",O21="Eligible"),"Eligible","Not Eligible"))
A22: 8 | B22: =IF($L$10="","",$L$10-(A22-1)*Settings!$B$12) -> 23150 | C22: =IF(B22="","",MROUND(B22*Settings!$B$7,Settings!$B$18)) -> 208.35 | E22: =IF(D22="","",IF(D22>=C22,"Eligible","Not Eligible")) | G22: =IF(F22="","",IF(F22>=Settings!$B$10,"Eligible","Not Eligible")) | H22: =IF(OR(E22="",G22=""),"",IF(AND(E22="Eligible",G22="Eligible"),"Eligible","Not Eligible")) | I22: 8 | J22: =IF($L$8="","",$L$8+(I22-1)*Settings!$B$12) -> 23550 | K22: =IF(J22="","",MROUND(J22*Settings!$B$7,Settings!$B$18)) -> 211.95 | M22: =IF(L22="","",IF(L22>=K22,"Eligible","Not Eligible")) | O22: =IF(N22="","",IF(N22>=Settings!$B$10,"Eligible","Not Eligible")) | P22: =IF(OR(M22="",O22=""),"",IF(AND(M22="Eligible",O22="Eligible"),"Eligible","Not Eligible"))
A23: 9 | B23: =IF($L$10="","",$L$10-(A23-1)*Settings!$B$12) -> 23100 | C23: =IF(B23="","",MROUND(B23*Settings!$B$7,Settings!$B$18)) -> 207.9 | E23: =IF(D23="","",IF(D23>=C23,"Eligible","Not Eligible")) | G23: =IF(F23="","",IF(F23>=Settings!$B$10,"Eligible","Not Eligible")) | H23: =IF(OR(E23="",G23=""),"",IF(AND(E23="Eligible",G23="Eligible"),"Eligible","Not Eligible")) | I23: 9 | J23: =IF($L$8="","",$L$8+(I23-1)*Settings!$B$12) -> 23600 | K23: =IF(J23="","",MROUND(J23*Settings!$B$7,Settings!$B$18)) -> 212.4 | M23: =IF(L23="","",IF(L23>=K23,"Eligible","Not Eligible")) | O23: =IF(N23="","",IF(N23>=Settings!$B$10,"Eligible","Not Eligible")) | P23: =IF(OR(M23="",O23=""),"",IF(AND(M23="Eligible",O23="Eligible"),"Eligible","Not Eligible"))
A24: 10 | B24: =IF($L$10="","",$L$10-(A24-1)*Settings!$B$12) -> 23050 | C24: =IF(B24="","",MROUND(B24*Settings!$B$7,Settings!$B$18)) -> 207.45 | E24: =IF(D24="","",IF(D24>=C24,"Eligible","Not Eligible")) | G24: =IF(F24="","",IF(F24>=Settings!$B$10,"Eligible","Not Eligible")) | H24: =IF(OR(E24="",G24=""),"",IF(AND(E24="Eligible",G24="Eligible"),"Eligible","Not Eligible")) | I24: 10 | J24: =IF($L$8="","",$L$8+(I24-1)*Settings!$B$12) -> 23650 | K24: =IF(J24="","",MROUND(J24*Settings!$B$7,Settings!$B$18)) -> 212.85 | M24: =IF(L24="","",IF(L24>=K24,"Eligible","Not Eligible")) | O24: =IF(N24="","",IF(N24>=Settings!$B$10,"Eligible","Not Eligible")) | P24: =IF(OR(M24="",O24=""),"",IF(AND(M24="Eligible",O24="Eligible"),"Eligible","Not Eligible"))
A26: FINAL NORMAL STRIKE SELECTION
A27: CALL Final Strike | C27: 23300 | D27: Expiry Date | F27: 46287 | G27: Status | H27: =IF(OR(C27="",F27=""),"INPUT REQUIRED",IF(COUNTIFS($B$15:$B$24,C27,$H$15:$H$24,"Eligible")=1,"READY","NOT ELIGIBLE")) -> NOT ELIGIBLE | I27: PUT Final Strike | K27: 23300 | L27: Expiry Date | N27: 46287 | O27: Status | P27: =IF(OR(K27="",N27=""),"INPUT REQUIRED",IF(COUNTIFS($J$15:$J$24,K27,$P$15:$P$24,"Eligible")=1,"READY","NOT ELIGIBLE")) -> NOT ELIGIBLE
A28: Only strikes that satisfy both premium and open-interest conditions appear in the dropdown lists.
A30: FINAL-STRIKE PREMIUM DATA — THREE DAYS
A31: CALL PREMIUM HISTORY | I31: PUT PREMIUM HISTORY
A32: Day | B32: High | C32: Low | I32: Day | J32: High | K32: Low
A33: Day 01 | B33: 461.15 | C33: 292.35 | I33: Day 01 | J33: 427.05 | K33: 268.75
A34: Day 02 | B34: 466.35 | C34: 201.05 | I34: Day 02 | J34: 526.3 | K34: 204.75
A35: Day 03 | B35: 347 | C35: 209 | I35: Day 03 | J35: 526.3 | K35: 204.75
A36: 3DHH | B36: =IF(COUNT(B33:B35)<3,"",MAX(B33:B35)) -> 466.35 | I36: 3DHH | J36: =IF(COUNT(J33:J35)<3,"",MAX(J33:J35)) -> 526.3
A37: 3DLL | C37: =IF(COUNT(C33:C35)<3,"",MIN(C33:C35)) -> 201.05 | I37: 3DLL | K37: =IF(COUNT(K33:K35)<3,"",MIN(K33:K35)) -> 204.75
A38: NORMAL ENTRY, TARGET & STOP-LOSS RESULTS
A39: Contract | B39: Final Strike | C39: Expiry | D39: Entry | E39: Target | F39: Stop-Loss | G39: Readiness | I39: Contract | J39: Final Strike | K39: Expiry | L39: Entry | M39: Target | N39: Stop-Loss | O39: Readiness
A40: CALL | B40: =IF($C$27="","",$C$27) -> 23300 | C40: =IF($F$27="","",$F$27) -> 46287 | D40: =IF(COUNT($B$33:$C$35)<6,"",MROUND($C$37*Settings!$B$14,Settings!$B$18)) -> 180.95 | E40: =IF(D40="","",MROUND(D40*Settings!$B$15,Settings!$B$18)) -> 45.25 | F40: =IF(OR(D40="",$B$36=""),"",MROUND(MIN(D40*Settings!$B$16,$B$36*Settings!$B$17),Settings!$B$18)) -> 316.65 | G40: =IF(H27<>"READY","READY",IF(COUNT(B33:C35)<6,"READY","READY")) -> READY | I40: PUT | J40: =IF($K$27="","",$K$27) -> 23300 | K40: =IF($N$27="","",$N$27) -> 46287 | L40: =IF(COUNT($J$33:$K$35)<6,"",MROUND($K$37*Settings!$B$14,Settings!$B$18)) -> 184.3 | M40: =IF(L40="","",MROUND(L40*Settings!$B$15,Settings!$B$18)) -> 46.1 | N40: =IF(OR(L40="",$J$36=""),"",MROUND(MIN(L40*Settings!$B$16,$J$36*Settings!$B$17),Settings!$B$18)) -> 322.55 | O40: =IF(P27<>"READY","READY",IF(COUNT(J33:K35)<6,"READY","READY")) -> READY
A42: GAP RECALCULATION — GAP UP PUT / GAP DOWN CALL
A43: GAP UP — PUT SELL | I43: GAP DOWN — CALL SELL
...

Sheet NIFTY Orders
C1: TRADING SECRETS ACADEMY PVT LTD | M1: NIFTY WEEKLY OPTIONS ORDER WORKSPACE
C2: Quality, Trust, Consistency & Ethics
C3: ORDER SELECTION, MISSED CHECKS & TICKETS
A4: Licence Number: TSA-MURU-2419 | Name: MURUGAN M | Mail ID: muruganm56789@gmail.com | Contact Number: 8610022419
A5: Number of Lots | B5: 1 | C5: Order Offset | D5: =Settings!$B$20 -> 3 | E5: Trading Date | F5: =IF('NIFTY Calculation'!$B$7="","",'NIFTY Calculation'!$B$7) -> 46286 | G5: Contract | H5: =IF('NIFTY Calculation'!$B$10="","",'NIFTY Calculation'!$B$10) -> NEXT WEEK EXPIRY | I5: Orders depend on this side's position, trade stage, complete levels and missed-order check. CALL and PUT operate independently.
A6: CALL MARKET INPUTS | I6: PUT MARKET INPUTS
A7: Open Price | B7: 240 | I7: Open Price
A8: First 10-Minute High | B8: 255 | I8: First 10-Minute High
A9: First 10-Minute Low | B9: 220 | C9: Trade Stage | I9: First 10-Minute Low | K9: Trade Stage
A10: CALL Position | B10: No Holding | I10: PUT Position | J10: No Holding
A12: SOURCE LEVELS FROM NIFTY CALCULATION
A13: Setup | B13: Contract | C13: Strike | D13: Expiry | E13: Entry | F13: Target | G13: Stop-Loss | H13: Readiness | J13: READINESS RULE READY requires an eligible final strike, expiry date, three days of premium data and complete gap inputs where applicable. Missing inputs return INPUT REQUIRED, never zero.
A14: =IF('NIFTY Calculation'!A71="","",'NIFTY Calculation'!A71) -> Normal CALL | B14: =IF('NIFTY Calculation'!B71="","",'NIFTY Calculation'!B71) -> CALL | C14: =IF('NIFTY Calculation'!C71="","",'NIFTY Calculation'!C71) -> 23300 | D14: =IF('NIFTY Calculation'!D71="","",'NIFTY Calculation'!D71) -> 46287 | E14: =IF('NIFTY Calculation'!E71="","",'NIFTY Calculation'!E71) -> 180.95 | F14: =IF('NIFTY Calculation'!F71="","",'NIFTY Calculation'!F71) -> 45.25 | G14: =IF('NIFTY Calculation'!G71="","",'NIFTY Calculation'!G71) -> 316.65 | H14: =IF('NIFTY Calculation'!H71="","",'NIFTY Calculation'!H71) -> READY
A15: =IF('NIFTY Calculation'!A72="","",'NIFTY Calculation'!A72) -> Gap Down CALL | B15: =IF('NIFTY Calculation'!B72="","",'NIFTY Calculation'!B72) -> CALL | C15: =IF('NIFTY Calculation'!C72="","",'NIFTY Calculation'!C72) -> 23650 | D15: =IF('NIFTY Calculation'!D72="","",'NIFTY Calculation'!D72) -> 46287 | E15: =IF('NIFTY Calculation'!E72="","",'NIFTY Calculation'!E72) -> 210.6 | F15: =IF('NIFTY Calculation'!F72="","",'NIFTY Calculation'!F72) -> 52.65 | G15: =IF('NIFTY Calculation'!G72="","",'NIFTY Calculation'!G72) -> 368.55 | H15: =IF('NIFTY Calculation'!H72="","",'NIFTY Calculation'!H72) -> READY
A16: =IF('NIFTY Calculation'!A73="","",'NIFTY Calculation'!A73) -> Normal PUT | B16: =IF('NIFTY Calculation'!B73="","",'NIFTY Calculation'!B73) -> PUT | C16: =IF('NIFTY Calculation'!C73="","",'NIFTY Calculation'!C73) -> 23300 | D16: =IF('NIFTY Calculation'!D73="","",'NIFTY Calculation'!D73) -> 46287 | E16: =IF('NIFTY Calculation'!E73="","",'NIFTY Calculation'!E73) -> 184.3 | F16: =IF('NIFTY Calculation'!F73="","",'NIFTY Calculation'!F73) -> 46.1 | G16: =IF('NIFTY Calculation'!G73="","",'NIFTY Calculation'!G73) -> 322.55 | H16: =IF('NIFTY Calculation'!H73="","",'NIFTY Calculation'!H73) -> READY
A17: =IF('NIFTY Calculation'!A74="","",'NIFTY Calculation'!A74) -> Gap Up PUT | B17: =IF('NIFTY Calculation'!B74="","",'NIFTY Calculation'!B74) -> PUT | C17: =IF('NIFTY Calculation'!C74="","",'NIFTY Calculation'!C74) -> 23100 | D17: =IF('NIFTY Calculation'!D74="","",'NIFTY Calculation'!D74) -> 46287 | E17: =IF('NIFTY Calculation'!E74="","",'NIFTY Calculation'!E74) -> 210.6 | F17: =IF('NIFTY Calculation'!F74="","",'NIFTY Calculation'!F74) -> 52.65 | G17: =IF('NIFTY Calculation'!G74="","",'NIFTY Calculation'!G74) -> 368.55 | H17: =IF('NIFTY Calculation'!H74="","",'NIFTY Calculation'!H74) -> READY
A19: SELECTED TRADING LEVELS & STATUS
A20: Side | B20: Selected Setup | C20: Trade Status | D20: Strike | E20: Expiry | F20: Entry | G20: Target | H20: Stop-Loss | I20: Level Status | K20: No Holding: B21/B22 selects Calculation levels. Holding: use the latest matching Tracking row, with the higher available recalculated or gap stop-loss. Each side has its own trade stage.
A21: CALL Sell | B21: Normal CALL | C21: =IF($C$10<>"",$C$10,IF($B$10="","",$B$10)) -> No Holding | D21: =IF($B$10="Call Sell Holding",IF(COUNTIFS('NIFTY Tracking'!$B$14:$B$213,"CALL Sell",'NIFTY Tracking'!$E$14:$E$213,"<>")>0,IF(INDEX('NIFTY Tracking'!$C$14:$C$213,LOOKUP(2,1/(('NIFTY Tracking'!$B$14:$B$213="CALL Sell")*('NIFTY Tracking'!$E$14:$E$213<>"")),ROW('NIFTY Tracking'!$B$14:$B$213)-ROW('NIFTY Tracking'!$B$14)+1))="","",INDEX('NIFTY Tracking'!$C$14:$C$213,LOOKUP(2,1/(('NIFTY Tracking'!$B$14:$B$213="CALL Sell")*('NIFTY Tracking'!$E$14:$E$213<>"")),ROW('NIFTY Tracking'!$B$14:$B$213)-ROW('NIFTY Tracking'!$B$14)+1))),""),IF($B$10="No Holding",IF($B21="","",IF(INDEX($C$14:$C$17,MATCH($B21,$A$14:$A$17,0))=0,"",INDEX($C$14:$C$17,MATCH($B21,$A$14:$A$17,0)))),"")) -> 23300 | E21: =IF($B$10="Call Sell Holding",IF(COUNTIFS('NIFTY Tracking'!$B$14:$B$213,"CALL Sell",'NIFTY Tracking'!$E$14:$E$213,"<>")>0,IF(INDEX('NIFTY Tracking'!$D$14:$D$213,LOOKUP(2,1/(('NIFTY Tracking'!$B$14:$B$213="CALL Sell")*('NIFTY Tracking'!$E$14:$E$213<>"")),ROW('NIFTY Tracking'!$B$14:$B$213)-ROW('NIFTY Tracking'!$B$14)+1))="","",INDEX('NIFTY Tracking'!$D$14:$D$213,LOOKUP(2,1/(('NIFTY Tracking'!$B$14:$B$213="CALL Sell")*('NIFTY Tracking'!$E$14:$E$213<>"")),ROW('NIFTY Tracking'!$B$14:$B$213)-ROW('NIFTY Tracking'!$B$14)+1))),""),IF($B$10="No Holding",IF($B21="","",IF(INDEX($D$14:$D$17,MATCH($B21,$A$14:$A$17,0))=0,"",INDEX($D$14:$D$17,MATCH($B21,$A$14:$A$17,0)))),"")) -> 46287 | F21: =IF($B$10="Call Sell Holding",IF(COUNTIFS('NIFTY Tracking'!$B$14:$B$213,"CALL Sell",'NIFTY Tracking'!$E$14:$E$213,"<>")>0,IF(INDEX('NIFTY Tracking'!$E$14:$E$213,LOOKUP(2,1/(('NIFTY Tracking'!$B$14:$B$213="CALL Sell")*('NIFTY Tracking'!$E$14:$E$213<>"")),ROW('NIFTY Tracking'!$B$14:$B$213)-ROW('NIFTY Tracking'!$B$14)+1))="","",INDEX('NIFTY Tracking'!$E$14:$E$213,LOOKUP(2,1/(('NIFTY Tracking'!$B$14:$B$213="CALL Sell")*('NIFTY Tracking'!$E$14:$E$213<>"")),ROW('NIFTY Tracking'!$B$14:$B$213)-ROW('NIFTY Tracking'!$B$14)+1))),""),IF($B$10="No Holding",IF($B21="","",IF(INDEX($E$14:$E$17,MATCH($B21,$A$14:$A$17,0))=0,"",INDEX($E$14:$E$17,MATCH($B21,$A$14:$A$17,0)))),"")) -> 180.95 | G21: =IF($B$10="Call Sell Holding",IF(COUNTIFS('NIFTY Tracking'!$B$14:$B$213,"CALL Sell",'NIFTY Tracking'!$E$14:$E$213,"<>")>0,IF(INDEX('NIFTY Tracking'!$F$14:$F$213,LOOKUP(2,1/(('NIFTY Tracking'!$B$14:$B$213="CALL Sell")*('NIFTY Tracking'!$E$14:$E$213<>"")),ROW('NIFTY Tracking'!$B$14:$B$213)-ROW('NIFTY Tracking'!$B$14)+1))="","",INDEX('NIFTY Tracking'!$F$14:$F$213,LOOKUP(2,1/(('NIFTY Tracking'!$B$14:$B$213="CALL Sell")*('NIFTY Tracking'!$E$14:$E$213<>"")),ROW('NIFTY Tracking'!$B$14:$B$213)-ROW('NIFTY Tracking'!$B$14)+1))),""),IF($B$10="No Holding",IF($B21="","",IF(INDEX($F$14:$F$17,MATCH($B21,$A$14:$A$17,0))=0,"",INDEX($F$14:$F$17,MATCH($B21,$A$14:$A$17,0)))),"")) -> 45.25 | H21: =IF($B$10="Call Sell Holding",IF(COUNTIFS('NIFTY Tracking'!$B$14:$B$213,"CALL Sell",'NIFTY Tracking'!$E$14:$E$213,"<>")>0,IF(IF(INDEX('NIFTY Tracking'!$K$14:$K$213,LOOKUP(2,1/(('NIFTY Tracking'!$B$14:$B$213="CALL Sell")*('NIFTY Tracking'!$E$14:$E$213<>"")),ROW('NIFTY Tracking'!$B$14:$B$213)-ROW('NIFTY Tracking'!$B$14)+1))="","",INDEX('NIFTY Tracking'!$K$14:$K$213,LOOKUP(2,1/(('NIFTY Tracking'!$B$14:$B$213="CALL Sell")*('NIFTY Tracking'!$E$14:$E$213<>"")),ROW('NIFTY Tracking'!$B$14:$B$213)-ROW('NIFTY Tracking'!$B$14)+1)))="",IF(INDEX('NIFTY Tracking'!$M$14:$M$213,LOOKUP(2,1/(('NIFTY Tracking'!$B$14:$B$213="CALL Sell")*('NIFTY Tracking'!$E$14:$E$213<>"")),ROW('NIFTY Tracking'!$B$14:$B$213)-ROW('NIFTY Tracking'!$B$14)+1))="","",INDEX('NIFTY Tracking'!$M$14:$M$213,LOOKUP(2,1/(('NIFTY Tracking'!$B$14:$B$213="CALL Sell")*('NIFTY Tracking'!$E$14:$E$213<>"")),ROW('NIFTY Tracking'!$B$14:$B$213)-ROW('NIFTY Tracking'!$B$14)+1))),IF(IF(INDEX('NIFTY Tracking'!$M$14:$M$213,LOOKUP(2,1/(('NIFTY Tracking'!$B$14:$B$213="CALL Sell")*('NIFTY Tracking'!$E$14:$E$213<>"")),ROW('NIFTY Tracking'!$B$14:$B$213)-ROW('NIFTY Tracking'!$B$14)+1))="","",INDEX('NIFTY Tracking'!$M$14:$M$213,LOOKUP(2,1/(('NIFTY Tracking'!$B$14:$B$213="CALL Sell")*('NIFTY Tracking'!$E$14:$E$213<>"")),ROW('NIFTY Tracking'!$B$14:$B$213)-ROW('NIFTY Tracking'!$B$14)+1)))="",IF(INDEX('NIFTY Tracking'!$K$14:$K$213,LOOKUP(2,1/(('NIFTY Tracking'!$B$14:$B$213="CALL Sell")*('NIFTY Tracking'!$E$14:$E$213<>"")),ROW('NIFTY Tracking'!$B$14:$B$213)-ROW('NIFTY Tracking'!$B$14)+1))="","",INDEX('NIFTY Tracking'!$K$14:$K$213,LOOKUP(2,1/(('NIFTY Tracking'!$B$14:$B$213="CALL Sell")*('NIFTY Tracking'!$E$14:$E$213<>"")),ROW('NIFTY Tracking'!$B$14:$B$213)-ROW('NIFTY Tracking'!$B$14)+1))),MAX(IF(INDEX('NIFTY Tracking'!$K$14:$K$213,LOOKUP(2,1/(('NIFTY Tracking'!$B$14:$B$213="CALL Sell")*('NIFTY Tracking'!$E$14:$E$213<>"")),ROW('NIFTY Tracking'!$B$14:$B$213)-ROW('NIFTY Tracking'!$B$14)+1))="","",INDEX('NIFTY Tracking'!$K$14:$K$213,LOOKUP(2,1/(('NIFTY Tracking'!$B$14:$B$213="CALL Sell")*('NIFTY Tracking'!$E$14:$E$213<>"")),ROW('NIFTY Tracking'!$B$14:$B$213)-ROW('NIFTY Tracking'!$B$14)+1))),IF(INDEX('NIFTY Tracking'!$M$14:$M$213,LOOKUP(2,1/(('NIFTY Tracking'!$B$14:$B$213="CALL Sell")*('NIFTY Tracking'!$E$14:$E$213<>"")),ROW('NIFTY Tracking'!$B$14:$B$213)-ROW('NIFTY Tracking'!$B$14)+1))="","",INDEX('NIFTY Tracking'!$M$14:$M$213,LOOKUP(2,1/(('NIFTY Tracking'!$B$14:$B$213="CALL Sell")*('NIFTY Tracking'!$E$14:$E$213<>"")),ROW('NIFTY Tracking'!$B$14:$B$213)-ROW('NIFTY Tracking'!$B$14)+1)))))),""),IF($B$10="No Holding",IF($B21="","",IF(INDEX($G$14:$G$17,MATCH($B21,$A$14:$A$17,0))=0,"",INDEX($G$14:$G$17,MATCH($B21,$A$14:$A$17,0)))),"")) -> 316.65 | I21: =IF($B$10="Call Sell Holding",IF(AND(D21<>"",ISNUMBER(E21),COUNT(F21:H21)=3),"READY","INPUT REQUIRED"),IF($B$10="No Holding",IF($B21="","INPUT REQUIRED",INDEX($H$14:$H$17,MATCH($B21,$A$14:$A$17,0))),"INPUT REQUIRED")) -> READY
A22: PUT Sell | B22: Normal PUT | C22: =IF($K$10<>"",$K$10,IF($J$10="","",$J$10)) -> No Holding | D22: =IF($J$10="Put Sell Holding",IF(COUNTIFS('NIFTY Tracking'!$B$14:$B$213,"PUT Sell",'NIFTY Tracking'!$E$14:$E$213,"<>")>0,IF(INDEX('NIFTY Tracking'!$C$14:$C$213,LOOKUP(2,1/(('NIFTY Tracking'!$B$14:$B$213="PUT Sell")*('NIFTY Tracking'!$E$14:$E$213<>"")),ROW('NIFTY Tracking'!$B$14:$B$213)-ROW('NIFTY Tracking'!$B$14)+1))="","",INDEX('NIFTY Tracking'!$C$14:$C$213,LOOKUP(2,1/(('NIFTY Tracking'!$B$14:$B$213="PUT Sell")*('NIFTY Tracking'!$E$14:$E$213<>"")),ROW('NIFTY Tracking'!$B$14:$B$213)-ROW('NIFTY Tracking'!$B$14)+1))),""),IF($J$10="No Holding",IF($B22="","",IF(INDEX($C$14:$C$17,MATCH($B22,$A$14:$A$17,0))=0,"",INDEX($C$14:$C$17,MATCH($B22,$A$14:$A$17,0)))),"")) -> 23300 | E22: =IF($J$10="Put Sell Holding",IF(COUNTIFS('NIFTY Tracking'!$B$14:$B$213,"PUT Sell",'NIFTY Tracking'!$E$14:$E$213,"<>")>0,IF(INDEX('NIFTY Tracking'!$D$14:$D$213,LOOKUP(2,1/(('NIFTY Tracking'!$B$14:$B$213="PUT Sell")*('NIFTY Tracking'!$E$14:$E$213<>"")),ROW('NIFTY Tracking'!$B$14:$B$213)-ROW('NIFTY Tracking'!$B$14)+1))="","",INDEX('NIFTY Tracking'!$D$14:$D$213,LOOKUP(2,1/(('NIFTY Tracking'!$B$14:$B$213="PUT Sell")*('NIFTY Tracking'!$E$14:$E$213<>"")),ROW('NIFTY Tracking'!$B$14:$B$213)-ROW('NIFTY Tracking'!$B$14)+1))),""),IF($J$10="No Holding",IF($B22="","",IF(INDEX($D$14:$D$17,MATCH($B22,$A$14:$A$17,0))=0,"",INDEX($D$14:$D$17,MATCH($B22,$A$14:$A$17,0)))),"")) -> 46287 | F22: =IF($J$10="Put Sell Holding",IF(COUNTIFS('NIFTY Tracking'!$B$14:$B$213,"PUT Sell",'NIFTY Tracking'!$E$14:$E$213,"<>")>0,IF(INDEX('NIFTY Tracking'!$E$14:$E$213,LOOKUP(2,1/(('NIFTY Tracking'!$B$14:$B$213="PUT Sell")*('NIFTY Tracking'!$E$14:$E$213<>"")),ROW('NIFTY Tracking'!$B$14:$B$213)-ROW('NIFTY Tracking'!$B$14)+1))="","",INDEX('NIFTY Tracking'!$E$14:$E$213,LOOKUP(2,1/(('NIFTY Tracking'!$B$14:$B$213="PUT Sell")*('NIFTY Tracking'!$E$14:$E$213<>"")),ROW('NIFTY Tracking'!$B$14:$B$213)-ROW('NIFTY Tracking'!$B$14)+1))),""),IF($J$10="No Holding",IF($B22="","",IF(INDEX($E$14:$E$17,MATCH($B22,$A$14:$A$17,0))=0,"",INDEX($E$14:$E$17,MATCH($B22,$A$14:$A$17,0)))),"")) -> 184.3 | G22: =IF($J$10="Put Sell Holding",IF(COUNTIFS('NIFTY Tracking'!$B$14:$B$213,"PUT Sell",'NIFTY Tracking'!$E$14:$E$213,"<>")>0,IF(INDEX('NIFTY Tracking'!$F$14:$F$213,LOOKUP(2,1/(('NIFTY Tracking'!$B$14:$B$213="PUT Sell")*('NIFTY Tracking'!$E$14:$E$213<>"")),ROW('NIFTY Tracking'!$B$14:$B$213)-ROW('NIFTY Tracking'!$B$14)+1))="","",INDEX('NIFTY Tracking'!$F$14:$F$213,LOOKUP(2,1/(('NIFTY Tracking'!$B$14:$B$213="PUT Sell")*('NIFTY Tracking'!$E$14:$E$213<>"")),ROW('NIFTY Tracking'!$B$14:$B$213)-ROW('NIFTY Tracking'!$B$14)+1))),""),IF($J$10="No Holding",IF($B22="","",IF(INDEX($F$14:$F$17,MATCH($B22,$A$14:$A$17,0))=0,"",INDEX($F$14:$F$17,MATCH($B22,$A$14:$A$17,0)))),"")) -> 46.1 | H22: =IF($J$10="Put Sell Holding",IF(COUNTIFS('NIFTY Tracking'!$B$14:$B$213,"PUT Sell",'NIFTY Tracking'!$E$14:$E$213,"<>")>0,IF(IF(INDEX('NIFTY Tracking'!$K$14:$K$213,LOOKUP(2,1/(('NIFTY Tracking'!$B$14:$B$213="PUT Sell")*('NIFTY Tracking'!$E$14:$E$213<>"")),ROW('NIFTY Tracking'!$B$14:$B$213)-ROW('NIFTY Tracking'!$B$14)+1))="","",INDEX('NIFTY Tracking'!$K$14:$K$213,LOOKUP(2,1/(('NIFTY Tracking'!$B$14:$B$213="PUT Sell")*('NIFTY Tracking'!$E$14:$E$213<>"")),ROW('NIFTY Tracking'!$B$14:$B$213)-ROW('NIFTY Tracking'!$B$14)+1)))="",IF(INDEX('NIFTY Tracking'!$M$14:$M$213,LOOKUP(2,1/(('NIFTY Tracking'!$B$14:$B$213="PUT Sell")*('NIFTY Tracking'!$E$14:$E$213<>"")),ROW('NIFTY Tracking'!$B$14:$B$213)-ROW('NIFTY Tracking'!$B$14)+1))="","",INDEX('NIFTY Tracking'!$M$14:$M$213,LOOKUP(2,1/(('NIFTY Tracking'!$B$14:$B$213="PUT Sell")*('NIFTY Tracking'!$E$14:$E$213<>"")),ROW('NIFTY Tracking'!$B$14:$B$213)-ROW('NIFTY Tracking'!$B$14)+1))),IF(IF(INDEX('NIFTY Tracking'!$M$14:$M$213,LOOKUP(2,1/(('NIFTY Tracking'!$B$14:$B$213="PUT Sell")*('NIFTY Tracking'!$E$14:$E$213<>"")),ROW('NIFTY Tracking'!$B$14:$B$213)-ROW('NIFTY Tracking'!$B$14)+1))="","",INDEX('NIFTY Tracking'!$M$14:$M$213,LOOKUP(2,1/(('NIFTY Tracking'!$B$14:$B$213="PUT Sell")*('NIFTY Tracking'!$E$14:$E$213<>"")),ROW('NIFTY Tracking'!$B$14:$B$213)-ROW('NIFTY Tracking'!$B$14)+1)))="",IF(INDEX('NIFTY Tracking'!$K$14:$K$213,LOOKUP(2,1/(('NIFTY Tracking'!$B$14:$B$213="PUT Sell")*('NIFTY Tracking'!$E$14:$E$213<>"")),ROW('NIFTY Tracking'!$B$14:$B$213)-ROW('NIFTY Tracking'!$B$14)+1))="","",INDEX('NIFTY Tracking'!$K$14:$K$213,LOOKUP(2,1/(('NIFTY Tracking'!$B$14:$B$213="PUT Sell")*('NIFTY Tracking'!$E$14:$E$213<>"")),ROW('NIFTY Tracking'!$B$14:$B$213)-ROW('NIFTY Tracking'!$B$14)+1))),MAX(IF(INDEX('NIFTY Tracking'!$K$14:$K$213,LOOKUP(2,1/(('NIFTY Tracking'!$B$14:$B$213="PUT Sell")*('NIFTY Tracking'!$E$14:$E$213<>"")),ROW('NIFTY Tracking'!$B$14:$B$213)-ROW('NIFTY Tracking'!$B$14)+1))="","",INDEX('NIFTY Tracking'!$K$14:$K$213,LOOKUP(2,1/(('NIFTY Tracking'!$B$14:$B$213="PUT Sell")*('NIFTY Tracking'!$E$14:$E$213<>"")),ROW('NIFTY Tracking'!$B$14:$B$213)-ROW('NIFTY Tracking'!$B$14)+1))),IF(INDEX('NIFTY Tracking'!$M$14:$M$213,LOOKUP(2,1/(('NIFTY Tracking'!$B$14:$B$213="PUT Sell")*('NIFTY Tracking'!$E$14:$E$213<>"")),ROW('NIFTY Tracking'!$B$14:$B$213)-ROW('NIFTY Tracking'!$B$14)+1))="","",INDEX('NIFTY Tracking'!$M$14:$M$213,LOOKUP(2,1/(('NIFTY Tracking'!$B$14:$B$213="PUT Sell")*('NIFTY Tracking'!$E$14:$E$213<>"")),ROW('NIFTY Tracking'!$B$14:$B$213)-ROW('NIFTY Tracking'!$B$14)+1)))))),""),IF($J$10="No Holding",IF($B22="","",IF(INDEX($G$14:$G$17,MATCH($B22,$A$14:$A$17,0))=0,"",INDEX($G$14:$G$17,MATCH($B22,$A$14:$A$17,0)))),"")) -> 322.55 | I22: =IF($J$10="Put Sell Holding",IF(AND(D22<>"",ISNUMBER(E22),COUNT(F22:H22)=3),"READY","INPUT REQUIRED"),IF($J$10="No Holding",IF($B22="","INPUT REQUIRED",INDEX($H$14:$H$17,MATCH($B22,$A$14:$A$17,0))),"INPUT REQUIRED")) -> READY
A24: MISSED-ORDER CHECKING
A25: Side | B25: Check | C25: Compare Input | D25: Selected Level | E25: Result | F25: Final Value | G25: Instruction
A26: CALL Sell | B26: Entry | C26: =IF(AND($B$10="No Holding",$C$10=""),IF(ISNUMBER($B$9),$B$9,""),"") -> 220 | D26: =IF(ISNUMBER($F$21),$F$21,"") -> 180.95 | E26: =IF(NOT(AND($B$10="No Holding",$C$10="")),"NOT APPLICABLE",IF(OR($I$21<>"READY",NOT(ISNUMBER($B$9))),"INPUT REQUIRED",IF($B$9<=$F$21,"ENTRY MISSED","ENTRY NOT MISSED"))) -> ENTRY NOT MISSED | F26: =IF(E26="ENTRY NOT MISSED",D26,"") -> 180.95 | G26: =IF(AND($B$10="Call Sell Holding",$C$10=""),"Select a trade stage for the holding",IF(E26="INPUT REQUIRED","Complete CALL levels and market inputs",IF(E26="ENTRY MISSED","Do not place this setup; review Gap Down CALL after 9:30 AM",IF(E26="ENTRY NOT MISSED","Place the selected CALL Sell entry order","")))) -> Place the selected CALL Sell entry order
A27: CALL Sell | B27: Target | C27: =IF($C$10="Entry Triggered",IF(ISNUMBER($B$7),$B$7,""),"") | D27: =IF(ISNUMBER($G$21),$G$21,"") -> 45.25 | E27: =IF($C$10="Target Triggered","COMPLETED",IF(NOT($C$10="Entry Triggered"),"NOT APPLICABLE",IF(OR($I$21<>"READY",NOT(ISNUMBER($B$7))),"INPUT REQUIRED",IF($B$7<=$G$21,"TARGET MISSED","TARGET NOT MISSED")))) -> NOT APPLICABLE | F27: =IF(E27="TARGET NOT MISSED",D27,"") | G27: =IF($C$10="Target Triggered","START FRESH TRADE",IF(E27="TARGET NOT MISSED","Place the CALL target order",IF(E27="TARGET MISSED","Target price already traded; do not place a late target order",IF(E27="INPUT REQUIRED","Complete CALL levels and opening price",""))))
A28: CALL Sell | B28: Stop-Loss | C28: =IF($C$10="Entry Triggered",IF(ISNUMBER($B$8),$B$8,""),"") | D28: =IF(ISNUMBER($H$21),$H$21,"") -> 316.65 | E28: =IF($C$10="Stoploss Triggered","COMPLETED",IF(NOT($C$10="Entry Triggered"),"NOT APPLICABLE",IF(OR($I$21<>"READY",NOT(ISNUMBER($B$8))),"INPUT REQUIRED",IF($B$8>=$H$21,"STOPLOSS MISSED","STOPLOSS NOT MISSED")))) -> NOT APPLICABLE | F28: =IF(E28="STOPLOSS NOT MISSED",D28,"") | G28: =IF($C$10="Stoploss Triggered","START FRESH TRADE",IF(E28="STOPLOSS NOT MISSED","Place the CALL stop-loss order",IF(E28="STOPLOSS MISSED","Stop-loss price already traded; do not place a late order",IF(E28="INPUT REQUIRED","Complete CALL levels and 10-minute high",""))))
A29: PUT Sell | B29: Entry | C29: =IF(AND($J$10="No Holding",$K$10=""),IF(ISNUMBER($J$9),$J$9,""),"") | D29: =IF(ISNUMBER($F$22),$F$22,"") -> 184.3 | E29: =IF(NOT(AND($J$10="No Holding",$K$10="")),"NOT APPLICABLE",IF(OR($I$22<>"READY",NOT(ISNUMBER($J$9))),"INPUT REQUIRED",IF($J$9<=$F$22,"ENTRY MISSED","ENTRY NOT MISSED"))) -> INPUT REQUIRED | F29: =IF(E29="ENTRY NOT MISSED",D29,"") | G29: =IF(AND($J$10="Put Sell Holding",$K$10=""),"Select a trade stage for the holding",IF(E29="INPUT REQUIRED","Complete PUT levels and market inputs",IF(E29="ENTRY MISSED","Do not place this setup; review Gap Up PUT after 9:30 AM",IF(E29="ENTRY NOT MISSED","Place the selected PUT Sell entry order","")))) -> Complete PUT levels and market inputs
A30: PUT Sell | B30: Target | C30: =IF($K$10="Entry Triggered",IF(ISNUMBER($J$7),$J$7,""),"") | D30: =IF(ISNUMBER($G$22),$G$22,"") -> 46.1 | E30: =IF($K$10="Target Triggered","COMPLETED",IF(NOT($K$10="Entry Triggered"),"NOT APPLICABLE",IF(OR($I$22<>"READY",NOT(ISNUMBER($J$7))),"INPUT REQUIRED",IF($J$7<=$G$22,"TARGET MISSED","TARGET NOT MISSED")))) -> NOT APPLICABLE | F30: =IF(E30="TARGET NOT MISSED",D30,"") | G30: =IF($K$10="Target Triggered","START FRESH TRADE",IF(E30="TARGET NOT MISSED","Place the PUT target order",IF(E30="TARGET MISSED","Target price already traded; do not place a late target order",IF(E30="INPUT REQUIRED","Complete PUT levels and opening price",""))))
A31: PUT Sell | B31: Stop-Loss | C31: =IF($K$10="Entry Triggered",IF(ISNUMBER($J$8),$J$8,""),"") | D31: =IF(ISNUMBER($H$22),$H$22,"") -> 322.55 | E31: =IF($K$10="Stoploss Triggered","COMPLETED",IF(NOT($K$10="Entry Triggered"),"NOT APPLICABLE",IF(OR($I$22<>"READY",NOT(ISNUMBER($J$8))),"INPUT REQUIRED",IF($J$8>=$H$22,"STOPLOSS MISSED","STOPLOSS NOT MISSED")))) -> NOT APPLICABLE | F31: =IF(E31="STOPLOSS NOT MISSED",D31,"") | G31: =IF($K$10="Stoploss Triggered","START FRESH TRADE",IF(E31="STOPLOSS NOT MISSED","Place the PUT stop-loss order",IF(E31="STOPLOSS MISSED","Stop-loss price already traded; do not place a late order",IF(E31="INPUT REQUIRED","Complete PUT levels and 10-minute high",""))))
A33: ACTIONABLE ORDER TICKETS
A34: Purpose | B34: Place? | C34: Side | D34: Order Type | E34: Trigger | F34: Order / Limit | G34: Time | H34: Instruction | I34: Purpose | J34: Place? | K34: Side | L34: Order Type | M34: Trigger | N34: Order / Limit | O34: Time | P34: Instruction
A35: Entry | B35: =IF($E$26="ENTRY NOT MISSED","YES","") -> YES | C35: =IF(B35="YES","Sell","") -> Sell | D35: =IF(B35="YES","Stop-Limit","") -> Stop-Limit | E35: =IF(B35="YES",$F$21,"") -> 180.95 | F35: =IF(E35="","",E35-Settings!$B$20) -> 177.95 | G35: =IF(B35="YES",IF($B$21="Gap Down CALL","After 9:30 AM","After 9:25 AM"),"") -> After 9:25 AM | H35: =IF(OR($C$10="Target Triggered",$C$10="Stoploss Triggered"),"START FRESH TRADE",IF(AND($B$10="Call Sell Holding",$C$10=""),"SELECT TRADE STAGE",IF(B35="YES","Place the selected CALL Sell entry",""))) -> Place the selected CALL Sell entry | I35: Entry | J35: =IF($E$29="ENTRY NOT MISSED","YES","") | K35: =IF(J35="YES","Sell","") | L35: =IF(J35="YES","Stop-Limit","") | M35: =IF(J35="YES",$F$22,"") | N35: =IF(M35="","",M35-Settings!$B$20) | O35: =IF(J35="YES",IF($B$22="Gap Up PUT","After 9:30 AM","After 9:25 AM"),"") | P35: =IF(OR($K$10="Target Triggered",$K$10="Stoploss Triggered"),"START FRESH TRADE",IF(AND($J$10="Put Sell Holding",$K$10=""),"SELECT TRADE STAGE",IF(J35="YES","Place the selected PUT Sell entry","")))
A36: Target | B36: =IF($E$27="TARGET NOT MISSED","YES","") | C36: =IF(B36="YES","Buy","") | D36: =IF(B36="YES","Limit","") | F36: =IF(B36="YES",$G$21,"") | G36: =IF(B36="YES","After 9:15 AM","") | H36: =IF(B36="YES","Place the CALL target order","") | I36: Target | J36: =IF($E$30="TARGET NOT MISSED","YES","") | K36: =IF(J36="YES","Buy","") | L36: =IF(J36="YES","Limit","") | N36: =IF(J36="YES",$G$22,"") | O36: =IF(J36="YES","After 9:15 AM","") | P36: =IF(J36="YES","Place the PUT target order","")
A37: Stop-Loss | B37: =IF($E$28="STOPLOSS NOT MISSED","YES","") | C37: =IF(B37="YES","Buy","") | D37: =IF(B37="YES","Stop-Limit","") | E37: =IF(B37="YES",$H$21,"") | F37: =IF(E37="","",E37+Settings!$B$20) | G37: =IF(B37="YES","After 9:25 AM","") | H37: =IF(B37="YES","Place the CALL stop-loss order","") | I37: Stop-Loss | J37: =IF($E$31="STOPLOSS NOT MISSED","YES","") | K37: =IF(J37="YES","Buy","") | L37: =IF(J37="YES","Stop-Limit","") | M37: =IF(J37="YES",$H$22,"") | N37: =IF(M37="","",M37+Settings!$B$20) | O37: =IF(J37="YES","After 9:25 AM","") | P37: =IF(J37="YES","Place the PUT stop-loss order","")
A39: OPERATING CHECK Fresh: select No Holding and leave trade stage blank. Entry Triggered: target and stop-loss orders. Target/Stoploss Triggered: START FRESH TRADE for that side; the other side remains independent. Place only tickets showing YES.
C43: TRADING SECRETS ACADEMY PVT LTD | Quality, Trust, Consistency & Ethics
C44: Office Support: Mrs. Sathyavani +91 90425 87730 | Mrs. Suganya +91 80569 25382
C45: Calculations & Live Market Support: Mr. Vanaraja +91 72005 75175 | Mr. Gokul +91 72005 75154
C46: Registered: Sivaganga 630611 | Head Office: West Tambaram, Chennai 600045

Sheet NIFTY Tracking
C1: TRADING SECRETS ACADEMY PVT LTD | U1: NIFTY WEEKLY OPTIONS 200-TRADE REGISTER
C2: Quality, Trust, Consistency & Ethics
C3: TRADE TRACKING & PERFORMANCE
A4: Licence Number: TSA-MURU-2419 | Name: MURUGAN M | Mail ID: muruganm56789@gmail.com | Contact Number: 8610022419
A5: TRADING DEFAULTS | H5: OVERALL PERFORMANCE | N5: TRADE QUALITY | T5: WORKFLOW
H6: Total Profit / Loss | K6: =SUM(U14:U213) -> 49593.863 | N6: Winning Trades | O6: =COUNTIF(U14:U213,">0") -> 7 | T6: 1. Enter trade details and selected levels. 2. Enter New 3DHH or Gap 3DHH when required. 3. Select the final result. 4. Confirm Exit Price, P/L and Validation. 5. For rollover, enter the rollover exit price.
A7: Default Lot Size | B7: 65 | H7: Overall Return | K7: =IF(Settings!$B$23=0,"",K6/B8) -> 0.15498082 | N7: Losing Trades | O7: =COUNTIF(U14:U213,"<0") -> 4
A8: Default Capital | B8: 320000 | H8: Completed Trades | K8: =COUNTIF(O14:O213,"Target Hit")+COUNTIF(O14:O213,"Stoploss Hit")+COUNTIF(O14:O213,"Gap Up Stoploss")+COUNTIF(O14:O213,"Gap Down Stoploss")+COUNTIF(O14:O213,"Rollover") -> 11 | N8: Win Rate | O8: =IF(K8=0,"",O6/K8) -> 0.63636364
A9: History Preserved | B9: 12 rows | H9: Open Trades | K9: =COUNTIF(B14:B213,"CALL Sell")+COUNTIF(B14:B213,"PUT Sell")-K8 -> 1 | N9: Best Trade | O9: =IF(COUNT(U14:U213)=0,"",MAX(U14:U213)) -> 10075
A11: TRADE TRACKING — 200 ROWS
A12: TRADE DETAILS | E12: LEVELS & NORMAL STOP-LOSS RECALCULATION | L12: GAP RECALCULATION | O12: EXIT RESULTS | X12: VALIDATION
A13: Trade Date | B13: Trade Type | C13: Final Strike | D13: Expiry | E13: Entry | F13: Target | G13: Original Stop-Loss | H13: New 3DHH | I13: Maximum Stop-Loss | J13: 3DHH Stop-Loss | K13: Final Recalculated Stop-Loss | L13: First 15-Minute High | M13: Gap Stop-Loss | N13: Gap Calculation Type | O13: Result Status | P13: Exit Price Used | Q13: Lot Size | R13: Lots | S13: Total Quantity | T13: Capital Used | U13: Profit / Loss | V13: Return % | W13: Rollover Exit Price | X13: Validation / Remarks
A14: 46205 | B14: PUT Sell | C14: 24200 | D14: 46217 | E14: 190 | F14: 47 | G14: 332 | H14: 135.65 | I14: =IF(E14="","",MROUND(E14*Settings!$B$16,Settings!$B$19)) -> 332.5 | J14: =IF(H14="","",MROUND(H14*Settings!$B$17,Settings!$B$19)) -> 149.2 | K14: =IF(OR(I14="",J14=""),"",MROUND(MIN(I14,J14),Settings!$B$19)) -> 149.2 | M14: =IF(OR(E14="",L14=""),"",MROUND(MIN(E14*Settings!$B$16,L14*Settings!$B$17),Settings!$B$19)) | N14: =IF(B14="","",IF(B14="CALL Sell","Gap Up Calculation","Gap Down Calculation")) -> Gap Down Calculation | O14: Target Hit | P14: =IF(O14="","",IF(O14="Target Hit",F14,IF(O14="Stoploss Hit",K14,IF(OR(O14="Gap Up Stoploss",O14="Gap Down Stoploss"),M14,IF(O14="Rollover",W14,""))))) -> 47 | Q14: =$B$7 -> 65 | R14: 1 | S14: =IF(OR(Q14="",R14=""),"",Q14*R14) -> 65 | T14: 320000 | U14: =IF(OR(E14="",P14="",S14=""),"",(E14-P14)*S14) -> 9295 | V14: =IF(OR(U14="",T14="",T14=0),"",U14/T14) -> 0.029046875 | X14: =IF(OR(B14="",O14=""),"",IF(AND(B14="CALL Sell",O14="Gap Up Stoploss"),"CHECK: CALL Sell uses Gap Down Stoploss",IF(AND(B14="PUT Sell",O14="Gap Down Stoploss"),"CHECK: PUT Sell uses Gap Up Stoploss",IF(AND(O14="Rollover",W14=""),"INPUT REQUIRED: Rollover exit price",IF(AND(O14="Target Hit",F14=""),"INPUT REQUIRED: Target",IF(AND(O14="Stoploss Hit",K14=""),"INPUT REQUIRED: New 3DHH",IF(AND(OR(O14="Gap Up Stoploss",O14="Gap Down Stoploss"),M14=""),"INPUT REQUIRED: Gap 3DHH","OK"))))))) -> OK
A15: 46211 | B15: CALL Sell | C15: 24200 | D15: 46224 | E15: 205 | F15: 51 | G15: 359 | H15: 217.4 | I15: =IF(E15="","",MROUND(E15*Settings!$B$16,Settings!$B$19)) -> 358.8 | J15: =IF(H15="","",MROUND(H15*Settings!$B$17,Settings!$B$19)) -> 239.1 | K15: =IF(OR(I15="",J15=""),"",MROUND(MIN(I15,J15),Settings!$B$19)) -> 239.1 | M15: =IF(OR(E15="",L15=""),"",MROUND(MIN(E15*Settings!$B$16,L15*Settings!$B$17),Settings!$B$19)) | N15: =IF(B15="","",IF(B15="CALL Sell","Gap Up Calculation","Gap Down Calculation")) -> Gap Up Calculation | O15: Stoploss Hit | P15: =IF(O15="","",IF(O15="Target Hit",F15,IF(O15="Stoploss Hit",K15,IF(OR(O15="Gap Up Stoploss",O15="Gap Down Stoploss"),M15,IF(O15="Rollover",W15,""))))) -> 239.1 | Q15: =$B$7 -> 65 | R15: 1 | S15: =IF(OR(Q15="",R15=""),"",Q15*R15) -> 65 | T15: 320000 | U15: =IF(OR(E15="",P15="",S15=""),"",(E15-P15)*S15) -> -2216.5 | V15: =IF(OR(U15="",T15="",T15=0),"",U15/T15) -> -0.0069265625 | X15: =IF(OR(B15="",O15=""),"",IF(AND(B15="CALL Sell",O15="Gap Up Stoploss"),"CHECK: CALL Sell uses Gap Down Stoploss",IF(AND(B15="PUT Sell",O15="Gap Down Stoploss"),"CHECK: PUT Sell uses Gap Up Stoploss",IF(AND(O15="Rollover",W15=""),"INPUT REQUIRED: Rollover exit price",IF(AND(O15="Target Hit",F15=""),"INPUT REQUIRED: Target",IF(AND(O15="Stoploss Hit",K15=""),"INPUT REQUIRED: New 3DHH",IF(AND(OR(O15="Gap Up Stoploss",O15="Gap Down Stoploss"),M15=""),"INPUT REQUIRED: Gap 3DHH","OK"))))))) -> OK
A16: 46220 | B16: PUT Sell | C16: 24250 | D16: 46231 | E16: 206 | F16: 51 | G16: 360 | H16: 260.05 | I16: =IF(E16="","",MROUND(E16*Settings!$B$16,Settings!$B$19)) -> 360.5 | J16: =IF(H16="","",MROUND(H16*Settings!$B$17,Settings!$B$19)) -> 286.1 | K16: =IF(OR(I16="",J16=""),"",MROUND(MIN(I16,J16),Settings!$B$19)) -> 286.1 | M16: =IF(OR(E16="",L16=""),"",MROUND(MIN(E16*Settings!$B$16,L16*Settings!$B$17),Settings!$B$19)) | N16: =IF(B16="","",IF(B16="CALL Sell","Gap Up Calculation","Gap Down Calculation")) -> Gap Down Calculation | O16: Stoploss Hit | P16: =IF(O16="","",IF(O16="Target Hit",F16,IF(O16="Stoploss Hit",K16,IF(OR(O16="Gap Up Stoploss",O16="Gap Down Stoploss"),M16,IF(O16="Rollover",W16,""))))) -> 286.1 | Q16: =$B$7 -> 65 | R16: 1 | S16: =IF(OR(Q16="",R16=""),"",Q16*R16) -> 65 | T16: 320000 | U16: =IF(OR(E16="",P16="",S16=""),"",(E16-P16)*S16) -> -5206.5 | V16: =IF(OR(U16="",T16="",T16=0),"",U16/T16) -> -0.016270312 | X16: =IF(OR(B16="",O16=""),"",IF(AND(B16="CALL Sell",O16="Gap Up Stoploss"),"CHECK: CALL Sell uses Gap Down Stoploss",IF(AND(B16="PUT Sell",O16="Gap Down Stoploss"),"CHECK: PUT Sell uses Gap Up Stoploss",IF(AND(O16="Rollover",W16=""),"INPUT REQUIRED: Rollover exit price",IF(AND(O16="Target Hit",F16=""),"INPUT REQUIRED: Target",IF(AND(O16="Stoploss Hit",K16=""),"INPUT REQUIRED: New 3DHH",IF(AND(OR(O16="Gap Up Stoploss",O16="Gap Down Stoploss"),M16=""),"INPUT REQUIRED: Gap 3DHH","OK"))))))) -> OK
A17: 46225 | B17: CALL Sell | C17: 24100 | D17: 46238 | E17: 189 | F17: 47 | G17: 331 | H17: 143 | I17: =IF(E17="","",MROUND(E17*Settings!$B$16,Settings!$B$19)) -> 330.8 | J17: =IF(H17="","",MROUND(H17*Settings!$B$17,Settings!$B$19)) -> 157.3 | K17: =IF(OR(I17="",J17=""),"",MROUND(MIN(I17,J17),Settings!$B$19)) -> 157.3 | L17: 203.7 | M17: =IF(OR(E17="",L17=""),"",MROUND(MIN(E17*Settings!$B$16,L17*Settings!$B$17),Settings!$B$19)) -> 224.1 | N17: =IF(B17="","",IF(B17="CALL Sell","Gap Up Calculation","Gap Down Calculation")) -> Gap Up Calculation | O17: Gap Down Stoploss | P17: =IF(O17="","",IF(O17="Target Hit",F17,IF(O17="Stoploss Hit",K17,IF(OR(O17="Gap Up Stoploss",O17="Gap Down Stoploss"),M17,IF(O17="Rollover",W17,""))))) -> 224.1 | Q17: =$B$7 -> 65 | R17: 1 | S17: =IF(OR(Q17="",R17=""),"",Q17*R17) -> 65 | T17: 320000 | U17: =IF(OR(E17="",P17="",S17=""),"",(E17-P17)*S17) -> -2281.5 | V17: =IF(OR(U17="",T17="",T17=0),"",U17/T17) -> -0.0071296875 | X17: =IF(OR(B17="",O17=""),"",IF(AND(B17="CALL Sell",O17="Gap Up Stoploss"),"CHECK: CALL Sell uses Gap Down Stoploss",IF(AND(B17="PUT Sell",O17="Gap Down Stoploss"),"CHECK: PUT Sell uses Gap Up Stoploss",IF(AND(O17="Rollover",W17=""),"INPUT REQUIRED: Rollover exit price",IF(AND(O17="Target Hit",F17=""),"INPUT REQUIRED: Target",IF(AND(O17="Stoploss Hit",K17=""),"INPUT REQUIRED: New 3DHH",IF(AND(OR(O17="Gap Up Stoploss",O17="Gap Down Stoploss"),M17=""),"INPUT REQUIRED: Gap 3DHH","OK"))))))) -> OK
A18: 46230 | B18: PUT Sell | C18: 24000 | D18: 46238 | E18: 191 | F18: 48 | G18: 334 | H18: 228 | I18: =IF(E18="","",MROUND(E18*Settings!$B$16,Settings!$B$19)) -> 334.3 | J18: =IF(H18="","",MROUND(H18*Settings!$B$17,Settings!$B$19)) -> 250.8 | K18: =IF(OR(I18="",J18=""),"",MROUND(MIN(I18,J18),Settings!$B$19)) -> 250.8 | M18: =IF(OR(E18="",L18=""),"",MROUND(MIN(E18*Settings!$B$16,L18*Settings!$B$17),Settings!$B$19)) | N18: =IF(B18="","",IF(B18="CALL Sell","Gap Up Calculation","Gap Down Calculation")) -> Gap Down Calculation | O18: Target Hit | P18: =IF(O18="","",IF(O18="Target Hit",F18,IF(O18="Stoploss Hit",K18,IF(OR(O18="Gap Up Stoploss",O18="Gap Down Stoploss"),M18,IF(O18="Rollover",W18,""))))) -> 48 | Q18: =$B$7 -> 65 | R18: 1 | S18: =IF(OR(Q18="",R18=""),"",Q18*R18) -> 65 | T18: 320000 | U18: =IF(OR(E18="",P18="",S18=""),"",(E18-P18)*S18) -> 9295 | V18: =IF(OR(U18="",T18="",T18=0),"",U18/T18) -> 0.029046875 | X18: =IF(OR(B18="",O18=""),"",IF(AND(B18="CALL Sell",O18="Gap Up Stoploss"),"CHECK: CALL Sell uses Gap Down Stoploss",IF(AND(B18="PUT Sell",O18="Gap Down Stoploss"),"CHECK: PUT Sell uses Gap Up Stoploss",IF(AND(O18="Rollover",W18=""),"INPUT REQUIRED: Rollover exit price",IF(AND(O18="Target Hit",F18=""),"INPUT REQUIRED: Target",IF(AND(O18="Stoploss Hit",K18=""),"INPUT REQUIRED: New 3DHH",IF(AND(OR(O18="Gap Up Stoploss",O18="Gap Down Stoploss"),M18=""),"INPUT REQUIRED: Gap 3DHH","OK"))))))) -> OK
A19: 46233 | B19: PUT Sell | C19: 24350 | D19: 46245 | E19: 201 | F19: 50 | G19: 351 | H19: 186.65 | I19: =IF(E19="","",MROUND(E19*Settings!$B$16,Settings!$B$19)) -> 351.8 | J19: =IF(H19="","",MROUND(H19*Settings!$B$17,Settings!$B$19)) -> 205.3 | K19: =IF(OR(I19="",J19=""),"",MROUND(MIN(I19,J19),Settings!$B$19)) -> 205.3 | M19: =IF(OR(E19="",L19=""),"",MROUND(MIN(E19*Settings!$B$16,L19*Settings!$B$17),Settings!$B$19)) | N19: =IF(B19="","",IF(B19="CALL Sell","Gap Up Calculation","Gap Down Calculation")) -> Gap Down Calculation | O19: Target Hit | P19: =IF(O19="","",IF(O19="Target Hit",F19,IF(O19="Stoploss Hit",K19,IF(OR(O19="Gap Up Stoploss",O19="Gap Down Stoploss"),M19,IF(O19="Rollover",W19,""))))) -> 50 | Q19: =$B$7 -> 65 | R19: 1 | S19: =IF(OR(Q19="",R19=""),"",Q19*R19) -> 65 | T19: 320000 | U19: =IF(OR(E19="",P19="",S19=""),"",(E19-P19)*S19) -> 9815 | V19: =IF(OR(U19="",T19="",T19=0),"",U19/T19) -> 0.030671875 | X19: =IF(OR(B19="",O19=""),"",IF(AND(B19="CALL Sell",O19="Gap Up Stoploss"),"CHECK: CALL Sell uses Gap Down Stoploss",IF(AND(B19="PUT Sell",O19="Gap Down Stoploss"),"CHECK: PUT Sell uses Gap Up Stoploss",IF(AND(O19="Rollover",W19=""),"INPUT REQUIRED: Rollover exit price",IF(AND(O19="Target Hit",F19=""),"INPUT REQUIRED: Target",IF(AND(O19="Stoploss Hit",K19=""),"INPUT REQUIRED: New 3DHH",IF(AND(OR(O19="Gap Up Stoploss",O19="Gap Down Stoploss"),M19=""),"INPUT REQUIRED: Gap 3DHH","OK"))))))) -> OK
A20: 46245 | B20: CALL Sell | C20: 24550 | D20: 46259 | E20: 201 | F20: 50 | G20: 351 | H20: 378 | I20: =IF(E20="","",MROUND(E20*Settings!$B$16,Settings!$B$19)) -> 351.8 | J20: =IF(H20="","",MROUND(H20*Settings!$B$17,Settings!$B$19)) -> 415.8 | K20: =IF(OR(I20="",J20=""),"",MROUND(MIN(I20,J20),Settings!$B$19)) -> 351.8 | M20: =IF(OR(E20="",L20=""),"",MROUND(MIN(E20*Settings!$B$16,L20*Settings!$B$17),Settings!$B$19)) | N20: =IF(B20="","",IF(B20="CALL Sell","Gap Up Calculation","Gap Down Calculation")) -> Gap Up Calculation | O20: Target Hit | P20: =IF(O20="","",IF(O20="Target Hit",F20,IF(O20="Stoploss Hit",K20,IF(OR(O20="Gap Up Stoploss",O20="Gap Down Stoploss"),M20,IF(O20="Rollover",W20,""))))) -> 50 | Q20: =$B$7 -> 65 | R20: 1 | S20: =IF(OR(Q20="",R20=""),"",Q20*R20) -> 65 | T20: 320000 | U20: =IF(OR(E20="",P20="",S20=""),"",(E20-P20)*S20) -> 9815 | V20: =IF(OR(U20="",T20="",T20=0),"",U20/T20) -> 0.030671875 | X20: =IF(OR(B20="",O20=""),"",IF(AND(B20="CALL Sell",O20="Gap Up Stoploss"),"CHECK: CALL Sell uses Gap Down Stoploss",IF(AND(B20="PUT Sell",O20="Gap Down Stoploss"),"CHECK: PUT Sell uses Gap Up Stoploss",IF(AND(O20="Rollover",W20=""),"INPUT REQUIRED: Rollover exit price",IF(AND(O20="Target Hit",F20=""),"INPUT REQUIRED: Target",IF(AND(O20="Stoploss Hit",K20=""),"INPUT REQUIRED: New 3DHH",IF(AND(OR(O20="Gap Up Stoploss",O20="Gap Down Stoploss"),M20=""),"INPUT REQUIRED: Gap 3DHH","OK"))))))) -> OK
A21: 46253 | B21: CALL Sell | C21: 24100 | D21: 46266 | E21: 202.05 | F21: 50.5125 | G21: 353.5875 | H21: 312.95 | I21: =IF(E21="","",MROUND(E21*Settings!$B$16,Settings!$B$19)) -> 353.6 | J21: =IF(H21="","",MROUND(H21*Settings!$B$17,Settings!$B$19)) -> 344.2 | K21: =IF(OR(I21="",J21=""),"",MROUND(MIN(I21,J21),Settings!$B$19)) -> 344.2 | M21: =IF(OR(E21="",L21=""),"",MROUND(MIN(E21*Settings!$B$16,L21*Settings!$B$17),Settings!$B$19)) | N21: =IF(B21="","",IF(B21="CALL Sell","Gap Up Calculation","Gap Down Calculation")) -> Gap Up Calculation | O21: Target Hit | P21: =IF(O21="","",IF(O21="Target Hit",F21,IF(O21="Stoploss Hit",K21,IF(OR(O21="Gap Up Stoploss",O21="Gap Down Stoploss"),M21,IF(O21="Rollover",W21,""))))) -> 50.5125 | Q21: =$B$7 -> 65 | R21: 1 | S21: =IF(OR(Q21="",R21=""),"",Q21*R21) -> 65 | T21: 320000 | U21: =IF(OR(E21="",P21="",S21=""),"",(E21-P21)*S21) -> 9849.9375 | V21: =IF(OR(U21="",T21="",T21=0),"",U21/T21) -> 0.030781055 | X21: =IF(OR(B21="",O21=""),"",IF(AND(B21="CALL Sell",O21="Gap Up Stoploss"),"CHECK: CALL Sell uses Gap Down Stoploss",IF(AND(B21="PUT Sell",O21="Gap Down Stoploss"),"CHECK: PUT Sell uses Gap Up Stoploss",IF(AND(O21="Rollover",W21=""),"INPUT REQUIRED: Rollover exit price",IF(AND(O21="Target Hit",F21=""),"INPUT REQUIRED: Target",IF(AND(O21="Stoploss Hit",K21=""),"INPUT REQUIRED: New 3DHH",IF(AND(OR(O21="Gap Up Stoploss",O21="Gap Down Stoploss"),M21=""),"INPUT REQUIRED: Gap 3DHH","OK"))))))) -> OK
A22: 46254 | B22: PUT Sell | C22: 24300 | D22: 46273 | E22: 188.145 | F22: 47.03625 | G22: 329.25375 | H22: 227 | I22: =IF(E22="","",MROUND(E22*Settings!$B$16,Settings!$B$19)) -> 329.3 | J22: =IF(H22="","",MROUND(H22*Settings!$B$17,Settings!$B$19)) -> 249.7 | K22: =IF(OR(I22="",J22=""),"",MROUND(MIN(I22,J22),Settings!$B$19)) -> 249.7 | L22: 282.2 | M22: =IF(OR(E22="",L22=""),"",MROUND(MIN(E22*Settings!$B$16,L22*Settings!$B$17),Settings!$B$19)) -> 310.4 | N22: =IF(B22="","",IF(B22="CALL Sell","Gap Up Calculation","Gap Down Calculation")) -> Gap Down Calculation | O22: Gap Up Stoploss | P22: =IF(O22="","",IF(O22="Target Hit",F22,IF(O22="Stoploss Hit",K22,IF(OR(O22="Gap Up Stoploss",O22="Gap Down Stoploss"),M22,IF(O22="Rollover",W22,""))))) -> 310.4 | Q22: =$B$7 -> 65 | R22: 1 | S22: =IF(OR(Q22="",R22=""),"",Q22*R22) -> 65 | T22: 320000 | U22: =IF(OR(E22="",P22="",S22=""),"",(E22-P22)*S22) -> -7946.575 | V22: =IF(OR(U22="",T22="",T22=0),"",U22/T22) -> -0.024833047 | X22: =IF(OR(B22="",O22=""),"",IF(AND(B22="CALL Sell",O22="Gap Up Stoploss"),"CHECK: CALL Sell uses Gap Down Stoploss",IF(AND(B22="PUT Sell",O22="Gap Down Stoploss"),"CHECK: PUT Sell uses Gap Up Stoploss",IF(AND(O22="Rollover",W22=""),"INPUT REQUIRED: Rollover exit price",IF(AND(O22="Target Hit",F22=""),"INPUT REQUIRED: Target",IF(AND(O22="Stoploss Hit",K22=""),"INPUT REQUIRED: New 3DHH",IF(AND(OR(O22="Gap Up Stoploss",O22="Gap Down Stoploss"),M22=""),"INPUT REQUIRED: Gap 3DHH","OK"))))))) -> OK
A23: 46266 | B23: CALL Sell | C23: 23950 | D23: 46273 | E23: 206 | F23: 51 | G23: 360 | I23: =IF(E23="","",MROUND(E23*Settings!$B$16,Settings!$B$19)) -> 360.5 | J23: =IF(H23="","",MROUND(H23*Settings!$B$17,Settings!$B$19)) | K23: =IF(OR(I23="",J23=""),"",MROUND(MIN(I23,J23),Settings!$B$19)) | L23: 512 | M23: =IF(OR(E23="",L23=""),"",MROUND(MIN(E23*Settings!$B$16,L23*Settings!$B$17),Settings!$B$19)) -> 360.5 | N23: =IF(B23="","",IF(B23="CALL Sell","Gap Up Calculation","Gap Down Calculation")) -> Gap Up Calculation | O23: Target Hit | P23: =IF(O23="","",IF(O23="Target Hit",F23,IF(O23="Stoploss Hit",K23,IF(OR(O23="Gap Up Stoploss",O23="Gap Down Stoploss"),M23,IF(O23="Rollover",W23,""))))) -> 51 | Q23: =$B$7 -> 65 | R23: 1 | S23: =IF(OR(Q23="",R23=""),"",Q23*R23) -> 65 | T23: 320000 | U23: =IF(OR(E23="",P23="",S23=""),"",(E23-P23)*S23) -> 10075 | V23: =IF(OR(U23="",T23="",T23=0),"",U23/T23) -> 0.031484375 | X23: =IF(OR(B23="",O23=""),"",IF(AND(B23="CALL Sell",O23="Gap Up Stoploss"),"CHECK: CALL Sell uses Gap Down Stoploss",IF(AND(B23="PUT Sell",O23="Gap Down Stoploss"),"CHECK: PUT Sell uses Gap Up Stoploss",IF(AND(O23="Rollover",W23=""),"INPUT REQUIRED: Rollover exit price",IF(AND(O23="Target Hit",F23=""),"INPUT REQUIRED: Target",IF(AND(O23="Stoploss Hit",K23=""),"INPUT REQUIRED: New 3DHH",IF(AND(OR(O23="Gap Up Stoploss",O23="Gap Down Stoploss"),M23=""),"INPUT REQUIRED: Gap 3DHH","OK"))))))) -> OK
A24: 46273 | B24: CALL Sell | C24: 23600 | D24: 46280 | E24: 187 | F24: 47 | G24: 328 | I24: =IF(E24="","",MROUND(E24*Settings!$B$16,Settings!$B$19)) -> 327.3 | J24: =IF(H24="","",MROUND(H24*Settings!$B$17,Settings!$B$19)) | K24: =IF(OR(I24="",J24=""),"",MROUND(MIN(I24,J24),Settings!$B$19)) | M24: =IF(OR(E24="",L24=""),"",MROUND(MIN(E24*Settings!$B$16,L24*Settings!$B$17),Settings!$B$19)) | N24: =IF(B24="","",IF(B24="CALL Sell","Gap Up Calculation","Gap Down Calculation")) -> Gap Up Calculation | O24: Target Hit | P24: =IF(O24="","",IF(O24="Target Hit",F24,IF(O24="Stoploss Hit",K24,IF(OR(O24="Gap Up Stoploss",O24="Gap Down Stoploss"),M24,IF(O24="Rollover",W24,""))))) -> 47 | Q24: =$B$7 -> 65 | R24: 1 | S24: =IF(OR(Q24="",R24=""),"",Q24*R24) -> 65 | T24: 320000 | U24: =IF(OR(E24="",P24="",S24=""),"",(E24-P24)*S24) -> 9100 | V24: =IF(OR(U24="",T24="",T24=0),"",U24/T24) -> 0.0284375 | X24: =IF(OR(B24="",O24=""),"",IF(AND(B24="CALL Sell",O24="Gap Up Stoploss"),"CHECK: CALL Sell uses Gap Down Stoploss",IF(AND(B24="PUT Sell",O24="Gap Down Stoploss"),"CHECK: PUT Sell uses Gap Up Stoploss",IF(AND(O24="Rollover",W24=""),"INPUT REQUIRED: Rollover exit price",IF(AND(O24="Target Hit",F24=""),"INPUT REQUIRED: Target",IF(AND(O24="Stoploss Hit",K24=""),"INPUT REQUIRED: New 3DHH",IF(AND(OR(O24="Gap Up Stoploss",O24="Gap Down Stoploss"),M24=""),"INPUT REQUIRED: Gap 3DHH","OK"))))))) -> OK
A25: 46280 | B25: CALL Sell | C25: 23200 | D25: 46287 | E25: 194.4 | F25: 48.6 | G25: 340.2 | H25: 381 | I25: =IF(E25="","",MROUND(E25*Settings!$B$16,Settings!$B$19)) -> 340.2 | J25: =IF(H25="","",MROUND(H25*Settings!$B$17,Settings!$B$19)) -> 419.1 | K25: =IF(OR(I25="",J25=""),"",MROUND(MIN(I25,J25),Settings!$B$19)) -> 340.2 | M25: =IF(OR(E25="",L25=""),"",MROUND(MIN(E25*Settings!$B$16,L25*Settings!$B$17),Settings!$B$19)) | N25: =IF(B25="","",IF(B25="CALL Sell","Gap Up Calculation","Gap Down Calculation")) -> Gap Up Calculation | P25: =IF(O25="","",IF(O25="Target Hit",F25,IF(O25="Stoploss Hit",K25,IF(OR(O25="Gap Up Stoploss",O25="Gap Down Stoploss"),M25,IF(O25="Rollover",W25,""))))) | Q25: =$B$7 -> 65 | R25: 1 | S25: =IF(OR(Q25="",R25=""),"",Q25*R25) -> 65 | T25: 320000 | U25: =IF(OR(E25="",P25="",S25=""),"",(E25-P25)*S25) | V25: =IF(OR(U25="",T25="",T25=0),"",U25/T25) | X25: =IF(OR(B25="",O25=""),"",IF(AND(B25="CALL Sell",O25="Gap Up Stoploss"),"CHECK: CALL Sell uses Gap Down Stoploss",IF(AND(B25="PUT Sell",O25="Gap Down Stoploss"),"CHECK: PUT Sell uses Gap Up Stoploss",IF(AND(O25="Rollover",W25=""),"INPUT REQUIRED: Rollover exit price",IF(AND(O25="Target Hit",F25=""),"INPUT REQUIRED: Target",IF(AND(O25="Stoploss Hit",K25=""),"INPUT REQUIRED: New 3DHH",IF(AND(OR(O25="Gap Up Stoploss",O25="Gap Down Stoploss"),M25=""),"INPUT REQUIRED: Gap 3DHH","OK")))))))
I26: =IF(E26="","",MROUND(E26*Settings!$B$16,Settings!$B$19)) | J26: =IF(H26="","",MROUND(H26*Settings!$B$17,Settings!$B$19)) | K26: =IF(OR(I26="",J26=""),"",MROUND(MIN(I26,J26),Settings!$B$19)) | M26: =IF(OR(E26="",L26=""),"",MROUND(MIN(E26*Settings!$B$16,L26*Settings!$B$17),Settings!$B$19)) | N26: =IF(B26="","",IF(B26="CALL Sell","Gap Up Calculation","Gap Down Calculation")) | P26: =IF(O26="","",IF(O26="Target Hit",F26,IF(O26="Stoploss Hit",K26,IF(OR(O26="Gap Up Stoploss",O26="Gap Down Stoploss"),M26,IF(O26="Rollover",W26,""))))) | Q26: =$B$7 -> 65 | S26: =IF(OR(Q26="",R26=""),"",Q26*R26) | U26: =IF(OR(E26="",P26="",S26=""),"",(E26-P26)*S26) | V26: =IF(OR(U26="",T26="",T26=0),"",U26/T26) | X26: =IF(OR(B26="",O26=""),"",IF(AND(B26="CALL Sell",O26="Gap Up Stoploss"),"CHECK: CALL Sell uses Gap Down Stoploss",IF(AND(B26="PUT Sell",O26="Gap Down Stoploss"),"CHECK: PUT Sell uses Gap Up Stoploss",IF(AND(O26="Rollover",W26=""),"INPUT REQUIRED: Rollover exit price",IF(AND(O26="Target Hit",F26=""),"INPUT REQUIRED: Target",IF(AND(O26="Stoploss Hit",K26=""),"INPUT REQUIRED: New 3DHH",IF(AND(OR(O26="Gap Up Stoploss",O26="Gap Down Stoploss"),M26=""),"INPUT REQUIRED: Gap 3DHH","OK")))))))
I27: =IF(E27="","",MROUND(E27*Settings!$B$16,Settings!$B$19)) | J27: =IF(H27="","",MROUND(H27*Settings!$B$17,Settings!$B$19)) | K27: =IF(OR(I27="",J27=""),"",MROUND(MIN(I27,J27),Settings!$B$19)) | M27: =IF(OR(E27="",L27=""),"",MROUND(MIN(E27*Settings!$B$16,L27*Settings!$B$17),Settings!$B$19)) | N27: =IF(B27="","",IF(B27="CALL Sell","Gap Up Calculation","Gap Down Calculation")) | P27: =IF(O27="","",IF(O27="Target Hit",F27,IF(O27="Stoploss Hit",K27,IF(OR(O27="Gap Up Stoploss",O27="Gap Down Stoploss"),M27,IF(O27="Rollover",W27,""))))) | Q27: =$B$7 -> 65 | S27: =IF(OR(Q27="",R27=""),"",Q27*R27) | U27: =IF(OR(E27="",P27="",S27=""),"",(E27-P27)*S27) | V27: =IF(OR(U27="",T27="",T27=0),"",U27/T27) | X27: =IF(OR(B27="",O27=""),"",IF(AND(B27="CALL Sell",O27="Gap Up Stoploss"),"CHECK: CALL Sell uses Gap Down Stoploss",IF(AND(B27="PUT Sell",O27="Gap Down Stoploss"),"CHECK: PUT Sell uses Gap Up Stoploss",IF(AND(O27="Rollover",W27=""),"INPUT REQUIRED: Rollover exit price",IF(AND(O27="Target Hit",F27=""),"INPUT REQUIRED: Target",IF(AND(O27="Stoploss Hit",K27=""),"INPUT REQUIRED: New 3DHH",IF(AND(OR(O27="Gap Up Stoploss",O27="Gap Down Stoploss"),M27=""),"INPUT REQUIRED: Gap 3DHH","OK")))))))
