Workbook

Sheet Home
C1: TRADING SECRETS ACADEMY PVT LTD | D1: TRADING SECRETS ACADEMY PVT LTD | E1: TRADING SECRETS ACADEMY PVT LTD | F1: TRADING SECRETS ACADEMY PVT LTD | G1: TRADING SECRETS ACADEMY PVT LTD | H1: TRADING SECRETS ACADEMY PVT LTD | I1: TRADING SECRETS ACADEMY PVT LTD | J1: GOLDTEN | GOLDM | GOLD | K1: GOLDTEN | GOLDM | GOLD | L1: GOLDTEN | GOLDM | GOLD
C2: Quality, Trust, Consistency & Ethics | D2: Quality, Trust, Consistency & Ethics | E2: Quality, Trust, Consistency & Ethics | F2: Quality, Trust, Consistency & Ethics | G2: Quality, Trust, Consistency & Ethics | H2: Quality, Trust, Consistency & Ethics | I2: Quality, Trust, Consistency & Ethics | J2: GOLDTEN | GOLDM | GOLD | K2: GOLDTEN | GOLDM | GOLD | L2: GOLDTEN | GOLDM | GOLD
C3: MCX GOLD FUTURES — PROFESSIONAL TRADING WORKBOOK | D3: MCX GOLD FUTURES — PROFESSIONAL TRADING WORKBOOK | E3: MCX GOLD FUTURES — PROFESSIONAL TRADING WORKBOOK | F3: MCX GOLD FUTURES — PROFESSIONAL TRADING WORKBOOK | G3: MCX GOLD FUTURES — PROFESSIONAL TRADING WORKBOOK | H3: MCX GOLD FUTURES — PROFESSIONAL TRADING WORKBOOK | I3: MCX GOLD FUTURES — PROFESSIONAL TRADING WORKBOOK | J3: GOLDTEN | GOLDM | GOLD | K3: GOLDTEN | GOLDM | GOLD | L3: GOLDTEN | GOLDM | GOLD
A4: Licence Number: TSA-MURU-2419 | Name: MURUGAN M | Mail ID: muruganm56789@gmail.com | Contact Number: 8610022419
A7: MCX GOLDTEN | B7: MCX GOLDTEN | C7: MCX GOLDTEN | D7: MCX GOLDTEN | E7: MCX GOLDM | F7: MCX GOLDM | G7: MCX GOLDM | H7: MCX GOLDM | I7: MCX GOLD | J7: MCX GOLD | K7: MCX GOLD | L7: MCX GOLD
A8: Open Calculation | B8: Open Calculation | C8: Open Calculation | D8: Open Calculation | E8: Open Calculation | F8: Open Calculation | G8: Open Calculation | H8: Open Calculation | I8: Open Calculation | J8: Open Calculation | K8: Open Calculation | L8: Open Calculation
A9: Open Orders | B9: Open Orders | C9: Open Orders | D9: Open Orders | E9: Open Orders | F9: Open Orders | G9: Open Orders | H9: Open Orders | I9: Open Orders | J9: Open Orders | K9: Open Orders | L9: Open Orders
A10: Open Tracking | B10: Open Tracking | C10: Open Tracking | D10: Open Tracking | E10: Open Tracking | F10: Open Tracking | G10: Open Tracking | H10: Open Tracking | I10: Open Tracking | J10: Open Tracking | K10: Open Tracking | L10: Open Tracking
A11: =IF('GOLDTEN Calculation'!B12="","Active Contract: input required","Active Contract: "&'GOLDTEN Calculation'!B12) -> Active Contract: OCT | B11: 10 | C11: 10 | D11: 10 | E11: =IF('GOLDM Calculation'!B12="","Active Contract: input required","Active Contract: "&'GOLDM Calculation'!B12) -> Active Contract: OCT | F11: 10 | G11: 10 | H11: 10 | I11: =IF('GOLD Calculation'!B12="","Active Contract: input required","Active Contract: "&'GOLD Calculation'!B12) -> Active Contract: OCT | J11: 10 | K11: 10 | L11: 10
A14: PORTFOLIO OVERVIEW | B14: PORTFOLIO OVERVIEW | C14: PORTFOLIO OVERVIEW | D14: PORTFOLIO OVERVIEW | E14: PORTFOLIO OVERVIEW | F14: PORTFOLIO OVERVIEW | G14: PORTFOLIO OVERVIEW | H14: PORTFOLIO OVERVIEW | I14: PORTFOLIO OVERVIEW | J14: PORTFOLIO OVERVIEW | K14: PORTFOLIO OVERVIEW | L14: PORTFOLIO OVERVIEW
A15: Capital Used (₹) | B15: Capital Used (₹) | C15: Total Profit / Loss (₹) | D15: Total Profit / Loss (₹) | E15: Portfolio Return | F15: Portfolio Return | G15: Completed Trades | H15: Completed Trades | I15: Winning Trades | J15: Winning Trades
A16: Capital Used (₹) | B16: Capital Used (₹) | C16: Total Profit / Loss (₹) | D16: Total Profit / Loss (₹) | E16: Portfolio Return | F16: Portfolio Return | G16: Completed Trades | H16: Completed Trades | I16: Winning Trades | J16: Winning Trades
A17: =SUM('GOLDTEN Tracking'!H7,'GOLDM Tracking'!H7,'GOLD Tracking'!H7) -> 900000 | B17: 10 | C17: =SUM('GOLDTEN Tracking'!H8,'GOLDM Tracking'!H8,'GOLD Tracking'!H8) -> 224718.03 | D17: 10 | E17: =IF(A17=0,"",C17/A17) -> 0.2496867 | F17: 10 | G17: =SUM('GOLDTEN Tracking'!H10,'GOLDM Tracking'!H10,'GOLD Tracking'!H10) -> 5 | H17: 10 | I17: =SUM('GOLDTEN Tracking'!L7,'GOLDM Tracking'!L7,'GOLD Tracking'!L7) -> 5 | J17: 10
A18: 10 | B18: 10 | C18: 10 | D18: 10 | E18: 10 | F18: 10 | G18: 10 | H18: 10 | I18: 10 | J18: 10
A21: PRODUCT STATUS | B21: PRODUCT STATUS | C21: PRODUCT STATUS | D21: PRODUCT STATUS | E21: PRODUCT STATUS | F21: PRODUCT STATUS | G21: PRODUCT STATUS | H21: PRODUCT STATUS | I21: PRODUCT STATUS | J21: PRODUCT STATUS | K21: PRODUCT STATUS | L21: PRODUCT STATUS
A22: Product | B22: Active Contract | C22: Next Date | D22: Buy Setup | E22: Buy Status | F22: Sell Setup | G22: Sell Status | H22: Total P&L (₹) | I22: Return | J22: DAILY WORKFLOW 1. Calculation: enter contract and four-day data. 2. Orders: select setup/status and enter market prices. 3. Tracking: record trade and exit results. | K22: DAILY WORKFLOW 1. Calculation: enter contract and four-day data. 2. Orders: select setup/status and enter market prices. 3. Tracking: record trade and exit results. | L22: DAILY WORKFLOW 1. Calculation: enter contract and four-day data. 2. Orders: select setup/status and enter market prices. 3. Tracking: record trade and exit results.
A23: MCX GOLDTEN | B23: =IF('GOLDTEN Calculation'!B12="","",'GOLDTEN Calculation'!B12) -> OCT | C23: =IF('GOLDTEN Calculation'!B6="","",'GOLDTEN Calculation'!B6) -> 46283 | D23: ='GOLDTEN Orders'!G21 -> Normal Buy | E23: ='GOLDTEN Orders'!F21 -> No Holdings | F23: ='GOLDTEN Orders'!G22 -> Latest Tracking Sell | G23: ='GOLDTEN Orders'!F22 -> Target Triggered | H23: ='GOLDTEN Tracking'!H8 -> 17529.342 | I23: ='GOLDTEN Tracking'!H9 -> 0.17529342 | J23: DAILY WORKFLOW 1. Calculation: enter contract and four-day data. 2. Orders: select setup/status and enter market prices. 3. Tracking: record trade and exit results. | K23: DAILY WORKFLOW 1. Calculation: enter contract and four-day data. 2. Orders: select setup/status and enter market prices. 3. Tracking: record trade and exit results. | L23: DAILY WORKFLOW 1. Calculation: enter contract and four-day data. 2. Orders: select setup/status and enter market prices. 3. Tracking: record trade and exit results.
A24: MCX GOLDM | B24: =IF('GOLDM Calculation'!B12="","",'GOLDM Calculation'!B12) -> OCT | C24: =IF('GOLDM Calculation'!B6="","",'GOLDM Calculation'!B6) -> 46275 | D24: ='GOLDM Orders'!G21 -> Normal Buy | E24: ='GOLDM Orders'!F21 -> Target Triggered | F24: ='GOLDM Orders'!G22 -> Latest Tracking Sell | G24: ='GOLDM Orders'!F22 -> Sell Holding | H24: ='GOLDM Tracking'!H8 -> 175293.42 | I24: ='GOLDM Tracking'!H9 -> 0.21911678 | J24: DAILY WORKFLOW 1. Calculation: enter contract and four-day data. 2. Orders: select setup/status and enter market prices. 3. Tracking: record trade and exit results. | K24: DAILY WORKFLOW 1. Calculation: enter contract and four-day data. 2. Orders: select setup/status and enter market prices. 3. Tracking: record trade and exit results. | L24: DAILY WORKFLOW 1. Calculation: enter contract and four-day data. 2. Orders: select setup/status and enter market prices. 3. Tracking: record trade and exit results.
A25: MCX GOLD | B25: =IF('GOLD Calculation'!B12="","",'GOLD Calculation'!B12) -> OCT | C25: =IF('GOLD Calculation'!B6="","",'GOLD Calculation'!B6) -> 46275 | D25: ='GOLD Orders'!G21 -> Gap Up Buy | E25: ='GOLD Orders'!F21 -> Entry Triggered | F25: ='GOLD Orders'!G22 -> Latest Tracking Sell | G25: ='GOLD Orders'!F22 -> Sell Holding | H25: ='GOLD Tracking'!H8 -> 31895.262 | I25: ='GOLD Tracking'!H9 | J25: DAILY WORKFLOW 1. Calculation: enter contract and four-day data. 2. Orders: select setup/status and enter market prices. 3. Tracking: record trade and exit results. | K25: DAILY WORKFLOW 1. Calculation: enter contract and four-day data. 2. Orders: select setup/status and enter market prices. 3. Tracking: record trade and exit results. | L25: DAILY WORKFLOW 1. Calculation: enter contract and four-day data. 2. Orders: select setup/status and enter market prices. 3. Tracking: record trade and exit results.
A28: INPUT COLOUR GUIDE | B28: INPUT COLOUR GUIDE | C28: INPUT COLOUR GUIDE | D28: INPUT COLOUR GUIDE | E28: INPUT COLOUR GUIDE | F28: INPUT COLOUR GUIDE | G28: INPUT COLOUR GUIDE | H28: INPUT COLOUR GUIDE | I28: INPUT COLOUR GUIDE | J28: INPUT COLOUR GUIDE | K28: INPUT COLOUR GUIDE | L28: INPUT COLOUR GUIDE
A29: BLUE Select from dropdown | B29: BLUE Select from dropdown | C29: BLUE Select from dropdown | D29: YELLOW Enter manually | E29: YELLOW Enter manually | F29: YELLOW Enter manually | G29: GREY / WHITE Calculated automatically | H29: GREY / WHITE Calculated automatically | I29: GREY / WHITE Calculated automatically | J29: GREEN / RED Buy / Sell workflow | K29: GREEN / RED Buy / Sell workflow | L29: GREEN / RED Buy / Sell workflow
A30: BLUE Select from dropdown | B30: BLUE Select from dropdown | C30: BLUE Select from dropdown | D30: YELLOW Enter manually | E30: YELLOW Enter manually | F30: YELLOW Enter manually | G30: GREY / WHITE Calculated automatically | H30: GREY / WHITE Calculated automatically | I30: GREY / WHITE Calculated automatically | J30: GREEN / RED Buy / Sell workflow | K30: GREEN / RED Buy / Sell workflow | L30: GREEN / RED Buy / Sell workflow
A31: BLUE Select from dropdown | B31: BLUE Select from dropdown | C31: BLUE Select from dropdown | D31: YELLOW Enter manually | E31: YELLOW Enter manually | F31: YELLOW Enter manually | G31: GREY / WHITE Calculated automatically | H31: GREY / WHITE Calculated automatically | I31: GREY / WHITE Calculated automatically | J31: GREEN / RED Buy / Sell workflow | K31: GREEN / RED Buy / Sell workflow | L31: GREEN / RED Buy / Sell workflow
A33: This workbook is a calculation and workflow tool. Verify exchange rules, broker requirements and live market conditions before placing any order. | B33: This workbook is a calculation and workflow tool. Verify exchange rules, broker requirements and live market conditions before placing any order. | C33: This workbook is a calculation and workflow tool. Verify exchange rules, broker requirements and live market conditions before placing any order. | D33: This workbook is a calculation and workflow tool. Verify exchange rules, broker requirements and live market conditions before placing any order. | E33: This workbook is a calculation and workflow tool. Verify exchange rules, broker requirements and live market conditions before placing any order. | F33: This workbook is a calculation and workflow tool. Verify exchange rules, broker requirements and live market conditions before placing any order. | G33: This workbook is a calculation and workflow tool. Verify exchange rules, broker requirements and live market conditions before placing any order. | H33: This workbook is a calculation and workflow tool. Verify exchange rules, broker requirements and live market conditions before placing any order. | I33: This workbook is a calculation and workflow tool. Verify exchange rules, broker requirements and live market conditions before placing any order. | J33: This workbook is a calculation and workflow tool. Verify exchange rules, broker requirements and live market conditions before placing any order. | K33: This workbook is a calculation and workflow tool. Verify exchange rules, broker requirements and live market conditions before placing any order. | L33: This workbook is a calculation and workflow tool. Verify exchange rules, broker requirements and live market conditions before placing any order.
A35: TRADING SECRETS ACADEMY PVT LTD | Quality, Trust, Consistency & Ethics
A36: Office Support: Mrs. Sathyavani +91 90425 87730 | Mrs. Suganya +91 80569 25382
A37: Calculations & Live Market Support: Mr. Vanaraja +91 7200575175 | Mr. Gokul +91 7200575154
A38: Registered: Sivaganga 630611 | Head Office: West Tambaram, Chennai 600045

Sheet GOLDTEN Calculation
A1: TRADING SECRETS ACADEMY PVT LTD | H1: MCX GOLDTEN CALCULATION | I1: MCX GOLDTEN CALCULATION | J1: MCX GOLDTEN CALCULATION
A2: Quality, Trust, Consistency & Ethics | H2: MCX GOLDTEN CALCULATION | I2: MCX GOLDTEN CALCULATION | J2: MCX GOLDTEN CALCULATION
A3: CALCULATION & TRADING LEVELS | H3: MCX GOLDTEN CALCULATION | I3: MCX GOLDTEN CALCULATION | J3: MCX GOLDTEN CALCULATION
A4: Licence Number: TSA-MURU-2419 | Name: MURUGAN M | Mail ID: muruganm56789@gmail.com | Contact Number: 8610022419
A5: CONTRACT & TRADING DATE INPUTS | B5: CONTRACT & TRADING DATE INPUTS | C5: CONTRACT & TRADING DATE INPUTS | D5: CONTRACT & TRADING DATE INPUTS
A6: Next Trading Date | B6: 46283
A7: Contract 1 | B7: SEP
A8: Contract 1 Expiry | B8: 46295
A9: Contract 2 | B9: OCT
A10: Contract 2 Expiry | B10: 46325
A11: Switch Date | B11: =IF(B8="","",WORKDAY(B8,-Settings!$K$11)) -> 46282
A12: Selected Contract | B12: =IF(OR(B6="",B11=""),"",IF(B6>=B11,B9,B7)) -> OCT
A14: FOUR-DAY HIGH / LOW INPUTS | B14: FOUR-DAY HIGH / LOW INPUTS | C14: FOUR-DAY HIGH / LOW INPUTS | D14: FOUR-DAY HIGH / LOW INPUTS | E14: FOUR-DAY HIGH / LOW INPUTS | F14: FOUR-DAY HIGH / LOW INPUTS | G14: FOUR-DAY HIGH / LOW INPUTS | H14: FOUR-DAY HIGH / LOW INPUTS | I14: FOUR-DAY HIGH / LOW INPUTS | J14: FOUR-DAY HIGH / LOW INPUTS
A16: Day | B16: Date | C16: High | D16: Low | F16: Summary Level | G16: Value
A17: Day 01 | B17: 46282 | C17: 154770 | D17: 151666 | F17: 4DHH | G17: =IF(COUNT(C17:C20)<4,"",MAX(C17:C20)) -> 154770
A18: Day 02 | C18: 154148 | D18: 150500 | F18: 4DLL | G18: =IF(COUNT(D17:D20)<4,"",MIN(D17:D20)) -> 150110
A19: Day 03 | C19: 152402 | D19: 150110 | F19: 2DHH | G19: =IF(COUNT(C19:C20)<2,"",MAX(C19:C20)) -> 152402
A20: Day 04 | C20: 151932 | D20: 150411 | F20: 2DLL | G20: =IF(COUNT(D19:D20)<2,"",MIN(D19:D20)) -> 150110
A22: NORMAL BUY | B22: NORMAL BUY | C22: NORMAL BUY | D22: NORMAL BUY | F22: NORMAL SELL | G22: NORMAL SELL | H22: NORMAL SELL | I22: NORMAL SELL | J22: NORMAL SELL
A23: Entry | B23: =IF(G17="","",G17*(1+Settings!$K$6)) -> 154955.72 | F23: Entry | G23: =IF(G18="","",G18*(1-Settings!$K$6)) -> 149929.87
A24: Target | B24: =IF(B23="","",B23*(1+Settings!$K$7)) -> 157280.06 | F24: Target | G24: =IF(G23="","",G23*(1-Settings!$K$7)) -> 147680.92
A25: Stoploss 1 | B25: =IF(OR(B23="",G20=""),"",MAX(B23*(1-Settings!$K$8),G20*(1-Settings!$K$6))) -> 152631.39 | F25: Stoploss 1 | G25: =IF(OR(G23="",G19=""),"",MIN(G23*(1+Settings!$K$8),G19*(1+Settings!$K$6))) -> 152178.82
A26: Stoploss 2 | B26: =IF(OR(B23="",G18=""),"",MAX(B23*(1-Settings!$K$8),G18*(1-Settings!$K$6))) -> 152631.39 | F26: Stoploss 2 | G26: =IF(OR(G23="",G17=""),"",MIN(G23*(1+Settings!$K$8),G17*(1+Settings!$K$6))) -> 152178.82
A29: NORMAL CALCULATION LEVELS — AUTO-LINKED TO ORDERS | B29: NORMAL CALCULATION LEVELS — AUTO-LINKED TO ORDERS | C29: NORMAL CALCULATION LEVELS — AUTO-LINKED TO ORDERS | D29: NORMAL CALCULATION LEVELS — AUTO-LINKED TO ORDERS | E29: NORMAL CALCULATION LEVELS — AUTO-LINKED TO ORDERS | F29: NORMAL CALCULATION LEVELS — AUTO-LINKED TO ORDERS | G29: NORMAL CALCULATION LEVELS — AUTO-LINKED TO ORDERS | H29: NORMAL CALCULATION LEVELS — AUTO-LINKED TO ORDERS
A30: Setup | B30: Order Date | C30: Contract | D30: Trade | E30: Entry | F30: Target | G30: Stoploss 1 | H30: Stoploss 2
A31: Normal Buy Levels | B31: =IF(B6="","",B6) -> 46283 | C31: =IF(B12="","",B12) -> OCT | D31: Buy | E31: =B23 -> 154955.72 | F31: =B24 -> 157280.06 | G31: =B25 -> 152631.39 | H31: =B26 -> 152631.39
A32: Normal Sell Levels | B32: =IF(B6="","",B6) -> 46283 | C32: =IF(B12="","",B12) -> OCT | D32: Sell | E32: =G23 -> 149929.87 | F32: =G24 -> 147680.92 | G32: =G25 -> 152178.82 | H32: =G26 -> 152178.82
A33: GAP-UP BUY & GAP-DOWN SELL LEVELS | B33: GAP-UP BUY & GAP-DOWN SELL LEVELS | C33: GAP-UP BUY & GAP-DOWN SELL LEVELS | D33: GAP-UP BUY & GAP-DOWN SELL LEVELS | E33: GAP-UP BUY & GAP-DOWN SELL LEVELS | F33: GAP-UP BUY & GAP-DOWN SELL LEVELS | G33: GAP-UP BUY & GAP-DOWN SELL LEVELS | H33: GAP-UP BUY & GAP-DOWN SELL LEVELS | I33: GAP-UP BUY & GAP-DOWN SELL LEVELS | J33: GAP-UP BUY & GAP-DOWN SELL LEVELS
A34: GAP-UP BUY | B34: GAP-UP BUY | C34: GAP-UP BUY | D34: GAP-UP BUY | F34: GAP-DOWN SELL | G34: GAP-DOWN SELL | H34: GAP-DOWN SELL | I34: GAP-DOWN SELL | J34: GAP-DOWN SELL
A35: First 15-Minute High | B35: 155090 | F35: First 15-Minute Low | G35: 149000
A36: Entry | B36: =IF(B35="","",B35*(1+Settings!$K$6)) -> 155276.11 | F36: Entry | G36: =IF(G35="","",G35*(1-Settings!$K$6)) -> 148821.2
A37: Target | B37: =IF(B36="","",B36*(1+Settings!$K$7)) -> 157605.25 | F37: Target | G37: =IF(G36="","",G36*(1-Settings!$K$7)) -> 146588.88
A38: Stoploss 1 | B38: =IF(OR(B35="",G20=""),"",MAX(B36*(1-Settings!$K$8),G20*(1-Settings!$K$6))) -> 152946.97 | F38: Stoploss 1 | G38: =IF(OR(G35="",G19=""),"",MIN(G36*(1+Settings!$K$8),G19*(1+Settings!$K$6))) -> 151053.52
A39: Stoploss 2 | B39: =IF(OR(B35="",G18=""),"",MAX(B36*(1-Settings!$K$8),G18*(1-Settings!$K$6))) -> 152946.97 | F39: Stoploss 2 | G39: =IF(OR(G35="",G17=""),"",MIN(G36*(1+Settings!$K$8),G17*(1+Settings!$K$6))) -> 151053.52
A41: GAP CALCULATION LEVELS — AUTO-LINKED TO ORDERS | B41: GAP CALCULATION LEVELS — AUTO-LINKED TO ORDERS | C41: GAP CALCULATION LEVELS — AUTO-LINKED TO ORDERS | D41: GAP CALCULATION LEVELS — AUTO-LINKED TO ORDERS | E41: GAP CALCULATION LEVELS — AUTO-LINKED TO ORDERS | F41: GAP CALCULATION LEVELS — AUTO-LINKED TO ORDERS | G41: GAP CALCULATION LEVELS — AUTO-LINKED TO ORDERS | H41: GAP CALCULATION LEVELS — AUTO-LINKED TO ORDERS
A42: Gap result cells stay blank until the corresponding first 15-minute value is entered. | B42: Gap result cells stay blank until the corresponding first 15-minute value is entered. | C42: Gap result cells stay blank until the corresponding first 15-minute value is entered. | D42: Gap result cells stay blank until the corresponding first 15-minute value is entered. | E42: Gap result cells stay blank until the corresponding first 15-minute value is entered. | F42: Gap result cells stay blank until the corresponding first 15-minute value is entered. | G42: Gap result cells stay blank until the corresponding first 15-minute value is entered. | H42: Gap result cells stay blank until the corresponding first 15-minute value is entered.
A43: Setup | B43: Order Date | C43: Contract | D43: Trade | E43: Entry | F43: Target | G43: Stoploss 1 | H43: Stoploss 2
A44: Gap Up Buy Levels | B44: =IF(B6="","",B6) -> 46283 | C44: =IF(B12="","",B12) -> OCT | D44: Buy | E44: =IF(B35="","",B36) -> 155276.11 | F44: =IF(B35="","",B37) -> 157605.25 | G44: =IF(B35="","",B38) -> 152946.97 | H44: =IF(B35="","",B39) -> 152946.97
A45: Gap Down Sell Levels | B45: =IF(B6="","",B6) -> 46283 | C45: =IF(B12="","",B12) -> OCT | D45: Sell | E45: =IF(G35="","",G36) -> 148821.2 | F45: =IF(G35="","",G37) -> 146588.88 | G45: =IF(G35="","",G38) -> 151053.52 | H45: =IF(G35="","",G39) -> 151053.52
A47: LEGEND: Yellow = manual input | Blue/grey = calculated | Green = Buy | Red = Sell | B47: LEGEND: Yellow = manual input | Blue/grey = calculated | Green = Buy | Red = Sell | C47: LEGEND: Yellow = manual input | Blue/grey = calculated | Green = Buy | Red = Sell | D47: LEGEND: Yellow = manual input | Blue/grey = calculated | Green = Buy | Red = Sell | E47: LEGEND: Yellow = manual input | Blue/grey = calculated | Green = Buy | Red = Sell | F47: LEGEND: Yellow = manual input | Blue/grey = calculated | Green = Buy | Red = Sell | G47: LEGEND: Yellow = manual input | Blue/grey = calculated | Green = Buy | Red = Sell | H47: LEGEND: Yellow = manual input | Blue/grey = calculated | Green = Buy | Red = Sell | I47: LEGEND: Yellow = manual input | Blue/grey = calculated | Green = Buy | Red = Sell | J47: LEGEND: Yellow = manual input | Blue/grey = calculated | Green = Buy | Red = Sell
...

Sheet GOLDTEN Orders
A1: TRADING SECRETS ACADEMY PVT LTD | G1: MCX GOLDTEN ORDERS | H1: MCX GOLDTEN ORDERS | I1: MCX GOLDTEN ORDERS
A2: Quality, Trust, Consistency & Ethics | G2: MCX GOLDTEN ORDERS | H2: MCX GOLDTEN ORDERS | I2: MCX GOLDTEN ORDERS
A3: ORDER SELECTION, MISSED CHECKS & TICKETS | G3: MCX GOLDTEN ORDERS | H3: MCX GOLDTEN ORDERS | I3: MCX GOLDTEN ORDERS
A4: Licence Number: TSA-MURU-2419 | Name: MURUGAN M | Mail ID: muruganm56789@gmail.com | Contact Number: 8610022419
A5: Number of Lots | B5: 2 | E5: Product | F5: MCX GOLDTEN
A6: Market Opening Price | B6: 154000 | E6: Active Contract | F6: =IF('GOLDTEN Calculation'!B12="","",'GOLDTEN Calculation'!B12) -> OCT
A7: First 10-Minute High | B7: 152500 | E7: Trading Date | F7: =IF('GOLDTEN Calculation'!B6="","",'GOLDTEN Calculation'!B6) -> 46283
A8: First 10-Minute Low | B8: 152800 | E8: Input Status | F8: =IF(COUNT(B6:B8)=3,"READY","INPUT REQUIRED") -> READY
A9: Buy Status | B9: No Holdings
A10: Sell Status | B10: Sell Holding | C10: Target Triggered
A12: SOURCE LEVELS FROM MATCHING CALCULATION SHEET | B12: SOURCE LEVELS FROM MATCHING CALCULATION SHEET | C12: SOURCE LEVELS FROM MATCHING CALCULATION SHEET | D12: SOURCE LEVELS FROM MATCHING CALCULATION SHEET | E12: SOURCE LEVELS FROM MATCHING CALCULATION SHEET | F12: SOURCE LEVELS FROM MATCHING CALCULATION SHEET | G12: SOURCE LEVELS FROM MATCHING CALCULATION SHEET | H12: SOURCE LEVELS FROM MATCHING CALCULATION SHEET | I12: SOURCE LEVELS FROM MATCHING CALCULATION SHEET
A13: Setup | B13: Entry | C13: Target | D13: SL1 | E13: SL2 | F13: Availability
A14: Normal Buy | B14: =IF(COUNT('GOLDTEN Calculation'!G17)=0,"",'GOLDTEN Calculation'!B23) -> 154955.72 | C14: =IF(COUNT('GOLDTEN Calculation'!G17)=0,"",'GOLDTEN Calculation'!B24) -> 157280.06 | D14: =IF(COUNT('GOLDTEN Calculation'!G17)=0,"",'GOLDTEN Calculation'!B25) -> 152631.39 | E14: =IF(COUNT('GOLDTEN Calculation'!G17)=0,"",'GOLDTEN Calculation'!B26) -> 152631.39 | F14: =IF(COUNT('GOLDTEN Calculation'!G17)=0,"INPUT REQUIRED",IF(COUNT(B14:E14)=4,"READY","INPUT REQUIRED")) -> READY
A15: Normal Sell | B15: =IF(COUNT('GOLDTEN Calculation'!G18)=0,"",'GOLDTEN Calculation'!G23) -> 149929.87 | C15: =IF(COUNT('GOLDTEN Calculation'!G18)=0,"",'GOLDTEN Calculation'!G24) -> 147680.92 | D15: =IF(COUNT('GOLDTEN Calculation'!G18)=0,"",'GOLDTEN Calculation'!G25) -> 152178.82 | E15: =IF(COUNT('GOLDTEN Calculation'!G18)=0,"",'GOLDTEN Calculation'!G26) -> 152178.82 | F15: =IF(COUNT('GOLDTEN Calculation'!G18)=0,"INPUT REQUIRED",IF(COUNT(B15:E15)=4,"READY","INPUT REQUIRED")) -> READY
A16: Gap Up Buy | B16: =IF(COUNT('GOLDTEN Calculation'!B35)=0,"",'GOLDTEN Calculation'!B36) -> 155276.11 | C16: =IF(COUNT('GOLDTEN Calculation'!B35)=0,"",'GOLDTEN Calculation'!B37) -> 157605.25 | D16: =IF(COUNT('GOLDTEN Calculation'!B35)=0,"",'GOLDTEN Calculation'!B38) -> 152946.97 | E16: =IF(COUNT('GOLDTEN Calculation'!B35)=0,"",'GOLDTEN Calculation'!B39) -> 152946.97 | F16: =IF(COUNT('GOLDTEN Calculation'!B35)=0,"INPUT REQUIRED",IF(COUNT(B16:E16)=4,"READY","INPUT REQUIRED")) -> READY
A17: Gap Down Sell | B17: =IF(COUNT('GOLDTEN Calculation'!G35)=0,"",'GOLDTEN Calculation'!G36) -> 148821.2 | C17: =IF(COUNT('GOLDTEN Calculation'!G35)=0,"",'GOLDTEN Calculation'!G37) -> 146588.88 | D17: =IF(COUNT('GOLDTEN Calculation'!G35)=0,"",'GOLDTEN Calculation'!G38) -> 151053.52 | E17: =IF(COUNT('GOLDTEN Calculation'!G35)=0,"",'GOLDTEN Calculation'!G39) -> 151053.52 | F17: =IF(COUNT('GOLDTEN Calculation'!G35)=0,"INPUT REQUIRED",IF(COUNT(B17:E17)=4,"READY","INPUT REQUIRED")) -> READY
A19: SELECTED TRADING LEVELS & STATUS | B19: SELECTED TRADING LEVELS & STATUS | C19: SELECTED TRADING LEVELS & STATUS | D19: SELECTED TRADING LEVELS & STATUS | E19: SELECTED TRADING LEVELS & STATUS | F19: SELECTED TRADING LEVELS & STATUS | G19: SELECTED TRADING LEVELS & STATUS | H19: SELECTED TRADING LEVELS & STATUS | I19: SELECTED TRADING LEVELS & STATUS
A20: Trade | B20: Entry | C20: Target | D20: Stoploss 1 | E20: Stoploss 2 | F20: Status | G20: Selected Setup
A21: Normal Buy | B21: =IF($B$9="Buy Holding",IFERROR(LOOKUP(2,1/(('GOLDTEN Tracking'!$D$14:$D$213="Buy")*('GOLDTEN Tracking'!$E$14:$E$213<>"")),'GOLDTEN Tracking'!$E$14:$E$213),""),IF($A$21="Normal Buy",IF(ISNUMBER(B14),B14,""),IF($A$21="Gap Up Buy",IF(ISNUMBER(B16),B16,""),""))) -> 154955.72 | C21: =IF($B$9="Buy Holding",IFERROR(LOOKUP(2,1/(('GOLDTEN Tracking'!$D$14:$D$213="Buy")*('GOLDTEN Tracking'!$E$14:$E$213<>"")),'GOLDTEN Tracking'!$F$14:$F$213),""),IF($A$21="Normal Buy",IF(ISNUMBER(C14),C14,""),IF($A$21="Gap Up Buy",IF(ISNUMBER(C16),C16,""),""))) -> 157280.06 | D21: =IF($B$9="Buy Holding",IFERROR(IF(AND(LOOKUP(2,1/(('GOLDTEN Tracking'!$D$14:$D$213="Buy")*('GOLDTEN Tracking'!$E$14:$E$213<>"")),'GOLDTEN Tracking'!$K$14:$K$213)="",LOOKUP(2,1/(('GOLDTEN Tracking'!$D$14:$D$213="Buy")*('GOLDTEN Tracking'!$E$14:$E$213<>"")),'GOLDTEN Tracking'!$Q$14:$Q$213)=""),"",IF(LOOKUP(2,1/(('GOLDTEN Tracking'!$D$14:$D$213="Buy")*('GOLDTEN Tracking'!$E$14:$E$213<>"")),'GOLDTEN Tracking'!$K$14:$K$213)="",LOOKUP(2,1/(('GOLDTEN Tracking'!$D$14:$D$213="Buy")*('GOLDTEN Tracking'!$E$14:$E$213<>"")),'GOLDTEN Tracking'!$Q$14:$Q$213),IF(LOOKUP(2,1/(('GOLDTEN Tracking'!$D$14:$D$213="Buy")*('GOLDTEN Tracking'!$E$14:$E$213<>"")),'GOLDTEN Tracking'!$Q$14:$Q$213)="",LOOKUP(2,1/(('GOLDTEN Tracking'!$D$14:$D$213="Buy")*('GOLDTEN Tracking'!$E$14:$E$213<>"")),'GOLDTEN Tracking'!$K$14:$K$213),MIN(LOOKUP(2,1/(('GOLDTEN Tracking'!$D$14:$D$213="Buy")*('GOLDTEN Tracking'!$E$14:$E$213<>"")),'GOLDTEN Tracking'!$K$14:$K$213),LOOKUP(2,1/(('GOLDTEN Tracking'!$D$14:$D$213="Buy")*('GOLDTEN Tracking'!$E$14:$E$213<>"")),'GOLDTEN Tracking'!$Q$14:$Q$213))))),""),IF($A$21="Normal Buy",IF(ISNUMBER(D14),D14,""),IF($A$21="Gap Up Buy",IF(ISNUMBER(D16),D16,""),""))) -> 152631.39 | E21: =IF($B$9="Buy Holding",IFERROR(IF(AND(LOOKUP(2,1/(('GOLDTEN Tracking'!$D$14:$D$213="Buy")*('GOLDTEN Tracking'!$E$14:$E$213<>"")),'GOLDTEN Tracking'!$N$14:$N$213)="",LOOKUP(2,1/(('GOLDTEN Tracking'!$D$14:$D$213="Buy")*('GOLDTEN Tracking'!$E$14:$E$213<>"")),'GOLDTEN Tracking'!$T$14:$T$213)=""),"",IF(LOOKUP(2,1/(('GOLDTEN Tracking'!$D$14:$D$213="Buy")*('GOLDTEN Tracking'!$E$14:$E$213<>"")),'GOLDTEN Tracking'!$N$14:$N$213)="",LOOKUP(2,1/(('GOLDTEN Tracking'!$D$14:$D$213="Buy")*('GOLDTEN Tracking'!$E$14:$E$213<>"")),'GOLDTEN Tracking'!$T$14:$T$213),IF(LOOKUP(2,1/(('GOLDTEN Tracking'!$D$14:$D$213="Buy")*('GOLDTEN Tracking'!$E$14:$E$213<>"")),'GOLDTEN Tracking'!$T$14:$T$213)="",LOOKUP(2,1/(('GOLDTEN Tracking'!$D$14:$D$213="Buy")*('GOLDTEN Tracking'!$E$14:$E$213<>"")),'GOLDTEN Tracking'!$N$14:$N$213),MIN(LOOKUP(2,1/(('GOLDTEN Tracking'!$D$14:$D$213="Buy")*('GOLDTEN Tracking'!$E$14:$E$213<>"")),'GOLDTEN Tracking'!$N$14:$N$213),LOOKUP(2,1/(('GOLDTEN Tracking'!$D$14:$D$213="Buy")*('GOLDTEN Tracking'!$E$14:$E$213<>"")),'GOLDTEN Tracking'!$T$14:$T$213))))),""),IF($A$21="Normal Buy",IF(ISNUMBER(E14),E14,""),IF($A$21="Gap Up Buy",IF(ISNUMBER(E16),E16,""),""))) -> 152631.39 | F21: =IF($C$9<>"",$C$9,IF($B$9="","",$B$9)) -> No Holdings | G21: =IF($B$9="Buy Holding","Latest Tracking Buy",IF($A$21="","",$A$21)) -> Normal Buy
A22: Normal Sell | B22: =IF($B$10="Sell Holding",IFERROR(LOOKUP(2,1/(('GOLDTEN Tracking'!$D$14:$D$213="Sell")*('GOLDTEN Tracking'!$E$14:$E$213<>"")),'GOLDTEN Tracking'!$E$14:$E$213),""),IF($A$22="Normal Sell",IF(ISNUMBER(B15),B15,""),IF($A$22="Gap Down Sell",IF(ISNUMBER(B17),B17,""),""))) -> 149929.87 | C22: =IF($B$10="Sell Holding",IFERROR(LOOKUP(2,1/(('GOLDTEN Tracking'!$D$14:$D$213="Sell")*('GOLDTEN Tracking'!$E$14:$E$213<>"")),'GOLDTEN Tracking'!$F$14:$F$213),""),IF($A$22="Normal Sell",IF(ISNUMBER(C15),C15,""),IF($A$22="Gap Down Sell",IF(ISNUMBER(C17),C17,""),""))) -> 147680.92 | D22: =IF($B$10="Sell Holding",IFERROR(IF(AND(LOOKUP(2,1/(('GOLDTEN Tracking'!$D$14:$D$213="Sell")*('GOLDTEN Tracking'!$E$14:$E$213<>"")),'GOLDTEN Tracking'!$K$14:$K$213)="",LOOKUP(2,1/(('GOLDTEN Tracking'!$D$14:$D$213="Sell")*('GOLDTEN Tracking'!$E$14:$E$213<>"")),'GOLDTEN Tracking'!$Q$14:$Q$213)=""),"",IF(LOOKUP(2,1/(('GOLDTEN Tracking'!$D$14:$D$213="Sell")*('GOLDTEN Tracking'!$E$14:$E$213<>"")),'GOLDTEN Tracking'!$K$14:$K$213)="",LOOKUP(2,1/(('GOLDTEN Tracking'!$D$14:$D$213="Sell")*('GOLDTEN Tracking'!$E$14:$E$213<>"")),'GOLDTEN Tracking'!$Q$14:$Q$213),IF(LOOKUP(2,1/(('GOLDTEN Tracking'!$D$14:$D$213="Sell")*('GOLDTEN Tracking'!$E$14:$E$213<>"")),'GOLDTEN Tracking'!$Q$14:$Q$213)="",LOOKUP(2,1/(('GOLDTEN Tracking'!$D$14:$D$213="Sell")*('GOLDTEN Tracking'!$E$14:$E$213<>"")),'GOLDTEN Tracking'!$K$14:$K$213),MAX(LOOKUP(2,1/(('GOLDTEN Tracking'!$D$14:$D$213="Sell")*('GOLDTEN Tracking'!$E$14:$E$213<>"")),'GOLDTEN Tracking'!$K$14:$K$213),LOOKUP(2,1/(('GOLDTEN Tracking'!$D$14:$D$213="Sell")*('GOLDTEN Tracking'!$E$14:$E$213<>"")),'GOLDTEN Tracking'!$Q$14:$Q$213))))),""),IF($A$22="Normal Sell",IF(ISNUMBER(D15),D15,""),IF($A$22="Gap Down Sell",IF(ISNUMBER(D17),D17,""),""))) -> 152583 | E22: =IF($B$10="Sell Holding",IFERROR(IF(AND(LOOKUP(2,1/(('GOLDTEN Tracking'!$D$14:$D$213="Sell")*('GOLDTEN Tracking'!$E$14:$E$213<>"")),'GOLDTEN Tracking'!$N$14:$N$213)="",LOOKUP(2,1/(('GOLDTEN Tracking'!$D$14:$D$213="Sell")*('GOLDTEN Tracking'!$E$14:$E$213<>"")),'GOLDTEN Tracking'!$T$14:$T$213)=""),"",IF(LOOKUP(2,1/(('GOLDTEN Tracking'!$D$14:$D$213="Sell")*('GOLDTEN Tracking'!$E$14:$E$213<>"")),'GOLDTEN Tracking'!$N$14:$N$213)="",LOOKUP(2,1/(('GOLDTEN Tracking'!$D$14:$D$213="Sell")*('GOLDTEN Tracking'!$E$14:$E$213<>"")),'GOLDTEN Tracking'!$T$14:$T$213),IF(LOOKUP(2,1/(('GOLDTEN Tracking'!$D$14:$D$213="Sell")*('GOLDTEN Tracking'!$E$14:$E$213<>"")),'GOLDTEN Tracking'!$T$14:$T$213)="",LOOKUP(2,1/(('GOLDTEN Tracking'!$D$14:$D$213="Sell")*('GOLDTEN Tracking'!$E$14:$E$213<>"")),'GOLDTEN Tracking'!$N$14:$N$213),MAX(LOOKUP(2,1/(('GOLDTEN Tracking'!$D$14:$D$213="Sell")*('GOLDTEN Tracking'!$E$14:$E$213<>"")),'GOLDTEN Tracking'!$N$14:$N$213),LOOKUP(2,1/(('GOLDTEN Tracking'!$D$14:$D$213="Sell")*('GOLDTEN Tracking'!$E$14:$E$213<>"")),'GOLDTEN Tracking'!$T$14:$T$213))))),""),IF($A$22="Normal Sell",IF(ISNUMBER(E15),E15,""),IF($A$22="Gap Down Sell",IF(ISNUMBER(E17),E17,""),""))) -> 152983 | F22: =IF($C$10<>"",$C$10,IF($B$10="","",$B$10)) -> Target Triggered | G22: =IF($B$10="Sell Holding","Latest Tracking Sell",IF($A$22="","",$A$22)) -> Latest Tracking Sell
A25: Check | B25: Order Direction | C25: Compare Input | D25: Selected Level | E25: Result | F25: Instruction | G25: Final Value
A26: Buy Entry | B26: Buy | C26: First 10-Min High | D26: Selected Buy Entry | E26: =IF(OR($B$9<>"No Holdings",$C$9<>"",NOT(ISNUMBER($B$21)),NOT(ISNUMBER($B$7))),"",IF($B$7>=$B$21,"MISSED","NOT MISSED")) -> NOT MISSED | F26: =IF(E26="","",IF(E26="MISSED",IF($A$21="Normal Buy","WAIT FOR GAP-UP INPUT","DO NOT PLACE — ENTRY PASSED"),IF($A$21="Normal Buy","PLACE AFTER 9:10 AM","PLACE AFTER 9:15 AM"))) -> PLACE AFTER 9:10 AM | G26: =IF(AND($B$9="No Holdings",$C$9="",ISNUMBER($B$21)),ROUND($B$21,0),"") -> 154956
A27: Sell Entry | B27: Sell | C27: First 10-Min Low | D27: Selected Sell Entry | E27: =IF(OR($B$10<>"No Holdings",$C$10<>"",NOT(ISNUMBER($B$22)),NOT(ISNUMBER($B$8))),"",IF($B$8<=$B$22,"MISSED","NOT MISSED")) | F27: =IF(E27="","",IF(E27="MISSED",IF($A$22="Normal Sell","WAIT FOR GAP-DOWN INPUT","DO NOT PLACE — ENTRY PASSED"),IF($A$22="Normal Sell","PLACE AFTER 9:10 AM","PLACE AFTER 9:15 AM"))) | G27: =IF(AND($B$10="No Holdings",$C$10="",ISNUMBER($B$22)),ROUND($B$22,0),"")
A28: Buy Target | B28: Sell | C28: Opening Price | D28: Selected Buy Target | E28: =IF(OR($C$9<>"Entry Triggered",NOT(ISNUMBER($C$21)),NOT(ISNUMBER($B$6))),"",IF($B$6>=$C$21,"MISSED","NOT MISSED")) | F28: =IF(E28="","",IF(E28="MISSED","EXIT AT CURRENT MARKET PRICE","PLACE LIMIT ORDER AT 9:00 AM")) | G28: =IF(AND($C$9="Entry Triggered",ISNUMBER($C$21)),ROUND($C$21,0),"")
A29: Sell Target | B29: Buy | C29: Opening Price | D29: Selected Sell Target | E29: =IF(OR($C$10<>"Entry Triggered",NOT(ISNUMBER($C$22)),NOT(ISNUMBER($B$6))),"",IF($B$6<=$C$22,"MISSED","NOT MISSED")) | F29: =IF(E29="","",IF(E29="MISSED","EXIT AT CURRENT MARKET PRICE","PLACE LIMIT ORDER AT 9:00 AM")) | G29: =IF(AND($C$10="Entry Triggered",ISNUMBER($C$22)),ROUND($C$22,0),"")
A30: Buy SL1 | B30: Sell | C30: First 10-Min Low | D30: Selected Buy SL1 | E30: =IF(OR($C$9<>"Entry Triggered",NOT(ISNUMBER($D$21)),NOT(ISNUMBER($B$8))),"",IF($B$8<=$D$21,"MISSED","NOT MISSED")) | F30: =IF(E30="","",IF(E30="MISSED","WAIT FOR GAP-DOWN SL1","PLACE ORDER AT 9:10 AM")) | G30: =IF(AND($C$9="Entry Triggered",ISNUMBER($D$21)),ROUND($D$21,0),"")
A31: Buy SL2 | B31: Sell | C31: First 10-Min Low | D31: Selected Buy SL2 | E31: =IF(OR($C$9<>"Target Triggered",NOT(ISNUMBER($E$21)),NOT(ISNUMBER($B$8))),"",IF($B$8<=$E$21,"MISSED","NOT MISSED")) | F31: =IF(E31="","",IF(E31="MISSED","WAIT FOR GAP-DOWN SL2","PLACE ORDER AT 9:10 AM")) | G31: =IF(AND($C$9="Target Triggered",ISNUMBER($E$21)),ROUND($E$21,0),"")
A32: Sell SL1 | B32: Buy | C32: First 10-Min High | D32: Selected Sell SL1 | E32: =IF(OR($C$10<>"Entry Triggered",NOT(ISNUMBER($D$22)),NOT(ISNUMBER($B$7))),"",IF($B$7>=$D$22,"MISSED","NOT MISSED")) | F32: =IF(E32="","",IF(E32="MISSED","WAIT FOR GAP-UP SL1","PLACE ORDER AT 9:10 AM")) | G32: =IF(AND($C$10="Entry Triggered",ISNUMBER($D$22)),ROUND($D$22,0),"")
A33: Sell SL2 | B33: Buy | C33: First 10-Min High | D33: Selected Sell SL2 | E33: =IF(OR($C$10<>"Target Triggered",NOT(ISNUMBER($E$22)),NOT(ISNUMBER($B$7))),"",IF($B$7>=$E$22,"MISSED","NOT MISSED")) -> NOT MISSED | F33: =IF(E33="","",IF(E33="MISSED","WAIT FOR GAP-UP SL2","PLACE ORDER AT 9:10 AM")) -> PLACE ORDER AT 9:10 AM | G33: =IF(AND($C$10="Target Triggered",ISNUMBER($E$22)),ROUND($E$22,0),"") -> 152983
A36: BUY TRADE ORDER TICKET | B36: BUY TRADE ORDER TICKET | C36: BUY TRADE ORDER TICKET | D36: BUY TRADE ORDER TICKET | E36: BUY TRADE ORDER TICKET | F36: BUY TRADE ORDER TICKET | G36: BUY TRADE ORDER TICKET | H36: BUY TRADE ORDER TICKET | I36: BUY TRADE ORDER TICKET
A37: Level | B37: Direction | C37: Order Type | D37: Lots | E37: Trigger Price | F37: Price | G37: Limit Price | H37: Placing Time | I37: Instruction
A38: Entry | B38: Buy | C38: Stoploss Order | D38: =IF(AND($B$9="No Holdings",$C$9="",$E$26="NOT MISSED"),$B$5,"") -> 2 | E38: =IF(D38="","",$G$26) -> 154956 | F38: =IF(E38="","",ROUND(E38*(1+Settings!$K$9),0)) -> 155111 | H38: =IF(D38="","",IF($A$21="Normal Buy","After 9:10 AM","After 9:15 AM")) -> After 9:10 AM | I38: =IF(AND($B$9="No Holdings",$C$9=""),$F$26,"") -> PLACE AFTER 9:10 AM
A39: Target | B39: Sell | C39: Limit Order | D39: =IF(AND($C$9="Entry Triggered",$E$28="NOT MISSED"),$B$5/2,"") | G39: =IF(D39="","",$G$28) | H39: =IF(D39="","","9:00 AM") | I39: =IF($C$9="Entry Triggered",$F$28,"")
A40: Stoploss 1 | B40: Sell | C40: Stoploss Order | D40: =IF(AND($C$9="Entry Triggered",$E$30="NOT MISSED"),$B$5,"") | E40: =IF(D40="","",$G$30) | F40: =IF(E40="","",ROUND(E40*(1-Settings!$K$9),0)) | H40: =IF(D40="","","9:10 AM") | I40: =IF($C$9="Stoploss 1 Triggered","START FRESH ORDER",IF($C$9="Entry Triggered",$F$30,""))
A41: Stoploss 2 | B41: Sell | C41: Stoploss Order | D41: =IF(AND($C$9="Target Triggered",$E$31="NOT MISSED"),$B$5/2,"") | E41: =IF(D41="","",$G$31) | F41: =IF(E41="","",ROUND(E41*(1-Settings!$K$9),0)) | H41: =IF(D41="","","9:10 AM") | I41: =IF($C$9="Stoploss 2 Triggered","START FRESH ORDER",IF($C$9="Target Triggered",$F$31,""))
A44: SELL TRADE ORDER TICKET | B44: SELL TRADE ORDER TICKET | C44: SELL TRADE ORDER TICKET | D44: SELL TRADE ORDER TICKET | E44: SELL TRADE ORDER TICKET | F44: SELL TRADE ORDER TICKET | G44: SELL TRADE ORDER TICKET | H44: SELL TRADE ORDER TICKET | I44: SELL TRADE ORDER TICKET
A45: Level | B45: Direction | C45: Order Type | D45: Lots | E45: Trigger Price | F45: Price | G45: Limit Price | H45: Placing Time | I45: Instruction
A46: Entry | B46: Sell | C46: Stoploss Order | D46: =IF(AND($B$10="No Holdings",$C$10="",$E$27="NOT MISSED"),$B$5,"") | E46: =IF(D46="","",$G$27) | F46: =IF(E46="","",ROUND(E46*(1-Settings!$K$9),0)) | H46: =IF(D46="","",IF($A$22="Normal Sell","After 9:10 AM","After 9:15 AM")) | I46: =IF(AND($B$10="No Holdings",$C$10=""),$F$27,"")
A47: Target | B47: Buy | C47: Limit Order | D47: =IF(AND($C$10="Entry Triggered",$E$29="NOT MISSED"),$B$5/2,"") | G47: =IF(D47="","",$G$29) | H47: =IF(D47="","","9:00 AM") | I47: =IF($C$10="Entry Triggered",$F$29,"")
A48: Stoploss 1 | B48: Buy | C48: Stoploss Order | D48: =IF(AND($C$10="Entry Triggered",$E$32="NOT MISSED"),$B$5,"") | E48: =IF(D48="","",$G$32) | F48: =IF(E48="","",ROUND(E48*(1+Settings!$K$9),0)) | H48: =IF(D48="","","9:10 AM") | I48: =IF($C$10="Stoploss 1 Triggered","START FRESH ORDER FROM TOMORROW",IF($C$10="Entry Triggered",$F$32,""))
...

Sheet GOLDTEN Tracking
C1: TRADING SECRETS ACADEMY PVT LTD | D1: TRADING SECRETS ACADEMY PVT LTD | E1: TRADING SECRETS ACADEMY PVT LTD | F1: TRADING SECRETS ACADEMY PVT LTD | G1: TRADING SECRETS ACADEMY PVT LTD | H1: TRADING SECRETS ACADEMY PVT LTD | I1: TRADING SECRETS ACADEMY PVT LTD | J1: TRADING SECRETS ACADEMY PVT LTD | K1: TRADING SECRETS ACADEMY PVT LTD | L1: TRADING SECRETS ACADEMY PVT LTD | M1: TRADING SECRETS ACADEMY PVT LTD | N1: TRADING SECRETS ACADEMY PVT LTD | O1: TRADING SECRETS ACADEMY PVT LTD | P1: TRADING SECRETS ACADEMY PVT LTD | Q1: TRADING SECRETS ACADEMY PVT LTD | R1: TRADING SECRETS ACADEMY PVT LTD | S1: TRADING SECRETS ACADEMY PVT LTD | T1: TRADING SECRETS ACADEMY PVT LTD | U1: TRADING SECRETS ACADEMY PVT LTD | V1: TRADING SECRETS ACADEMY PVT LTD | W1: TRADING SECRETS ACADEMY PVT LTD | X1: MCX GOLDTEN 200-TRADE REGISTER | Y1: MCX GOLDTEN 200-TRADE REGISTER | Z1: MCX GOLDTEN 200-TRADE REGISTER
C2: Quality, Trust, Consistency & Ethics | D2: Quality, Trust, Consistency & Ethics | E2: Quality, Trust, Consistency & Ethics | F2: Quality, Trust, Consistency & Ethics | G2: Quality, Trust, Consistency & Ethics | H2: Quality, Trust, Consistency & Ethics | I2: Quality, Trust, Consistency & Ethics | J2: Quality, Trust, Consistency & Ethics | K2: Quality, Trust, Consistency & Ethics | L2: Quality, Trust, Consistency & Ethics | M2: Quality, Trust, Consistency & Ethics | N2: Quality, Trust, Consistency & Ethics | O2: Quality, Trust, Consistency & Ethics | P2: Quality, Trust, Consistency & Ethics | Q2: Quality, Trust, Consistency & Ethics | R2: Quality, Trust, Consistency & Ethics | S2: Quality, Trust, Consistency & Ethics | T2: Quality, Trust, Consistency & Ethics | U2: Quality, Trust, Consistency & Ethics | V2: Quality, Trust, Consistency & Ethics | W2: Quality, Trust, Consistency & Ethics | X2: MCX GOLDTEN 200-TRADE REGISTER | Y2: MCX GOLDTEN 200-TRADE REGISTER | Z2: MCX GOLDTEN 200-TRADE REGISTER
C3: TRADE TRACKING & PERFORMANCE | D3: TRADE TRACKING & PERFORMANCE | E3: TRADE TRACKING & PERFORMANCE | F3: TRADE TRACKING & PERFORMANCE | G3: TRADE TRACKING & PERFORMANCE | H3: TRADE TRACKING & PERFORMANCE | I3: TRADE TRACKING & PERFORMANCE | J3: TRADE TRACKING & PERFORMANCE | K3: TRADE TRACKING & PERFORMANCE | L3: TRADE TRACKING & PERFORMANCE | M3: TRADE TRACKING & PERFORMANCE | N3: TRADE TRACKING & PERFORMANCE | O3: TRADE TRACKING & PERFORMANCE | P3: TRADE TRACKING & PERFORMANCE | Q3: TRADE TRACKING & PERFORMANCE | R3: TRADE TRACKING & PERFORMANCE | S3: TRADE TRACKING & PERFORMANCE | T3: TRADE TRACKING & PERFORMANCE | U3: TRADE TRACKING & PERFORMANCE | V3: TRADE TRACKING & PERFORMANCE | W3: TRADE TRACKING & PERFORMANCE | X3: MCX GOLDTEN 200-TRADE REGISTER | Y3: MCX GOLDTEN 200-TRADE REGISTER | Z3: MCX GOLDTEN 200-TRADE REGISTER
A4: Licence Number: TSA-MURU-2419 | Name: MURUGAN M | Mail ID: muruganm56789@gmail.com | Contact Number: 8610022419
N5: WORKFLOW 1. Enter trade details and original levels. 2. Enter requested 2-day / 4-day or gap inputs when needed. 3. Select Exit 1 and Exit 2. 4. The sheet calculates each leg and reconciles Total P&L automatically. | O5: WORKFLOW 1. Enter trade details and original levels. 2. Enter requested 2-day / 4-day or gap inputs when needed. 3. Select Exit 1 and Exit 2. 4. The sheet calculates each leg and reconciles Total P&L automatically. | P5: WORKFLOW 1. Enter trade details and original levels. 2. Enter requested 2-day / 4-day or gap inputs when needed. 3. Select Exit 1 and Exit 2. 4. The sheet calculates each leg and reconciles Total P&L automatically. | Q5: WORKFLOW 1. Enter trade details and original levels. 2. Enter requested 2-day / 4-day or gap inputs when needed. 3. Select Exit 1 and Exit 2. 4. The sheet calculates each leg and reconciles Total P&L automatically. | R5: WORKFLOW 1. Enter trade details and original levels. 2. Enter requested 2-day / 4-day or gap inputs when needed. 3. Select Exit 1 and Exit 2. 4. The sheet calculates each leg and reconciles Total P&L automatically. | S5: WORKFLOW 1. Enter trade details and original levels. 2. Enter requested 2-day / 4-day or gap inputs when needed. 3. Select Exit 1 and Exit 2. 4. The sheet calculates each leg and reconciles Total P&L automatically. | T5: WORKFLOW 1. Enter trade details and original levels. 2. Enter requested 2-day / 4-day or gap inputs when needed. 3. Select Exit 1 and Exit 2. 4. The sheet calculates each leg and reconciles Total P&L automatically. | U5: WORKFLOW 1. Enter trade details and original levels. 2. Enter requested 2-day / 4-day or gap inputs when needed. 3. Select Exit 1 and Exit 2. 4. The sheet calculates each leg and reconciles Total P&L automatically. | V5: WORKFLOW 1. Enter trade details and original levels. 2. Enter requested 2-day / 4-day or gap inputs when needed. 3. Select Exit 1 and Exit 2. 4. The sheet calculates each leg and reconciles Total P&L automatically. | W5: WORKFLOW 1. Enter trade details and original levels. 2. Enter requested 2-day / 4-day or gap inputs when needed. 3. Select Exit 1 and Exit 2. 4. The sheet calculates each leg and reconciles Total P&L automatically. | X5: WORKFLOW 1. Enter trade details and original levels. 2. Enter requested 2-day / 4-day or gap inputs when needed. 3. Select Exit 1 and Exit 2. 4. The sheet calculates each leg and reconciles Total P&L automatically. | Y5: WORKFLOW 1. Enter trade details and original levels. 2. Enter requested 2-day / 4-day or gap inputs when needed. 3. Select Exit 1 and Exit 2. 4. The sheet calculates each leg and reconciles Total P&L automatically. | Z5: WORKFLOW 1. Enter trade details and original levels. 2. Enter requested 2-day / 4-day or gap inputs when needed. 3. Select Exit 1 and Exit 2. 4. The sheet calculates each leg and reconciles Total P&L automatically.
F6: OVERALL PERFORMANCE | G6: OVERALL PERFORMANCE | H6: OVERALL PERFORMANCE | J6: TRADE QUALITY | K6: TRADE QUALITY | L6: TRADE QUALITY | N6: WORKFLOW 1. Enter trade details and original levels. 2. Enter requested 2-day / 4-day or gap inputs when needed. 3. Select Exit 1 and Exit 2. 4. The sheet calculates each leg and reconciles Total P&L automatically. | O6: WORKFLOW 1. Enter trade details and original levels. 2. Enter requested 2-day / 4-day or gap inputs when needed. 3. Select Exit 1 and Exit 2. 4. The sheet calculates each leg and reconciles Total P&L automatically. | P6: WORKFLOW 1. Enter trade details and original levels. 2. Enter requested 2-day / 4-day or gap inputs when needed. 3. Select Exit 1 and Exit 2. 4. The sheet calculates each leg and reconciles Total P&L automatically. | Q6: WORKFLOW 1. Enter trade details and original levels. 2. Enter requested 2-day / 4-day or gap inputs when needed. 3. Select Exit 1 and Exit 2. 4. The sheet calculates each leg and reconciles Total P&L automatically. | R6: WORKFLOW 1. Enter trade details and original levels. 2. Enter requested 2-day / 4-day or gap inputs when needed. 3. Select Exit 1 and Exit 2. 4. The sheet calculates each leg and reconciles Total P&L automatically. | S6: WORKFLOW 1. Enter trade details and original levels. 2. Enter requested 2-day / 4-day or gap inputs when needed. 3. Select Exit 1 and Exit 2. 4. The sheet calculates each leg and reconciles Total P&L automatically. | T6: WORKFLOW 1. Enter trade details and original levels. 2. Enter requested 2-day / 4-day or gap inputs when needed. 3. Select Exit 1 and Exit 2. 4. The sheet calculates each leg and reconciles Total P&L automatically. | U6: WORKFLOW 1. Enter trade details and original levels. 2. Enter requested 2-day / 4-day or gap inputs when needed. 3. Select Exit 1 and Exit 2. 4. The sheet calculates each leg and reconciles Total P&L automatically. | V6: WORKFLOW 1. Enter trade details and original levels. 2. Enter requested 2-day / 4-day or gap inputs when needed. 3. Select Exit 1 and Exit 2. 4. The sheet calculates each leg and reconciles Total P&L automatically. | W6: WORKFLOW 1. Enter trade details and original levels. 2. Enter requested 2-day / 4-day or gap inputs when needed. 3. Select Exit 1 and Exit 2. 4. The sheet calculates each leg and reconciles Total P&L automatically. | X6: WORKFLOW 1. Enter trade details and original levels. 2. Enter requested 2-day / 4-day or gap inputs when needed. 3. Select Exit 1 and Exit 2. 4. The sheet calculates each leg and reconciles Total P&L automatically. | Y6: WORKFLOW 1. Enter trade details and original levels. 2. Enter requested 2-day / 4-day or gap inputs when needed. 3. Select Exit 1 and Exit 2. 4. The sheet calculates each leg and reconciles Total P&L automatically. | Z6: WORKFLOW 1. Enter trade details and original levels. 2. Enter requested 2-day / 4-day or gap inputs when needed. 3. Select Exit 1 and Exit 2. 4. The sheet calculates each leg and reconciles Total P&L automatically.
A7: TRADING INPUTS | F7: Capital Used (₹) | H7: 100000 | J7: Winning Trades | L7: =COUNTIF(Y14:Y213,">0") -> 2 | N7: WORKFLOW 1. Enter trade details and original levels. 2. Enter requested 2-day / 4-day or gap inputs when needed. 3. Select Exit 1 and Exit 2. 4. The sheet calculates each leg and reconciles Total P&L automatically. | O7: WORKFLOW 1. Enter trade details and original levels. 2. Enter requested 2-day / 4-day or gap inputs when needed. 3. Select Exit 1 and Exit 2. 4. The sheet calculates each leg and reconciles Total P&L automatically. | P7: WORKFLOW 1. Enter trade details and original levels. 2. Enter requested 2-day / 4-day or gap inputs when needed. 3. Select Exit 1 and Exit 2. 4. The sheet calculates each leg and reconciles Total P&L automatically. | Q7: WORKFLOW 1. Enter trade details and original levels. 2. Enter requested 2-day / 4-day or gap inputs when needed. 3. Select Exit 1 and Exit 2. 4. The sheet calculates each leg and reconciles Total P&L automatically. | R7: WORKFLOW 1. Enter trade details and original levels. 2. Enter requested 2-day / 4-day or gap inputs when needed. 3. Select Exit 1 and Exit 2. 4. The sheet calculates each leg and reconciles Total P&L automatically. | S7: WORKFLOW 1. Enter trade details and original levels. 2. Enter requested 2-day / 4-day or gap inputs when needed. 3. Select Exit 1 and Exit 2. 4. The sheet calculates each leg and reconciles Total P&L automatically. | T7: WORKFLOW 1. Enter trade details and original levels. 2. Enter requested 2-day / 4-day or gap inputs when needed. 3. Select Exit 1 and Exit 2. 4. The sheet calculates each leg and reconciles Total P&L automatically. | U7: WORKFLOW 1. Enter trade details and original levels. 2. Enter requested 2-day / 4-day or gap inputs when needed. 3. Select Exit 1 and Exit 2. 4. The sheet calculates each leg and reconciles Total P&L automatically. | V7: WORKFLOW 1. Enter trade details and original levels. 2. Enter requested 2-day / 4-day or gap inputs when needed. 3. Select Exit 1 and Exit 2. 4. The sheet calculates each leg and reconciles Total P&L automatically. | W7: WORKFLOW 1. Enter trade details and original levels. 2. Enter requested 2-day / 4-day or gap inputs when needed. 3. Select Exit 1 and Exit 2. 4. The sheet calculates each leg and reconciles Total P&L automatically. | X7: WORKFLOW 1. Enter trade details and original levels. 2. Enter requested 2-day / 4-day or gap inputs when needed. 3. Select Exit 1 and Exit 2. 4. The sheet calculates each leg and reconciles Total P&L automatically. | Y7: WORKFLOW 1. Enter trade details and original levels. 2. Enter requested 2-day / 4-day or gap inputs when needed. 3. Select Exit 1 and Exit 2. 4. The sheet calculates each leg and reconciles Total P&L automatically. | Z7: WORKFLOW 1. Enter trade details and original levels. 2. Enter requested 2-day / 4-day or gap inputs when needed. 3. Select Exit 1 and Exit 2. 4. The sheet calculates each leg and reconciles Total P&L automatically.
A8: Number of Lots | C8: 2 | F8: Overall Profit / Loss (₹) | H8: =SUM(Y14:Y213) -> 17529.342 | J8: Losing Trades | L8: =COUNTIF(Y14:Y213,"<0") -> 0 | N8: WORKFLOW 1. Enter trade details and original levels. 2. Enter requested 2-day / 4-day or gap inputs when needed. 3. Select Exit 1 and Exit 2. 4. The sheet calculates each leg and reconciles Total P&L automatically. | O8: WORKFLOW 1. Enter trade details and original levels. 2. Enter requested 2-day / 4-day or gap inputs when needed. 3. Select Exit 1 and Exit 2. 4. The sheet calculates each leg and reconciles Total P&L automatically. | P8: WORKFLOW 1. Enter trade details and original levels. 2. Enter requested 2-day / 4-day or gap inputs when needed. 3. Select Exit 1 and Exit 2. 4. The sheet calculates each leg and reconciles Total P&L automatically. | Q8: WORKFLOW 1. Enter trade details and original levels. 2. Enter requested 2-day / 4-day or gap inputs when needed. 3. Select Exit 1 and Exit 2. 4. The sheet calculates each leg and reconciles Total P&L automatically. | R8: WORKFLOW 1. Enter trade details and original levels. 2. Enter requested 2-day / 4-day or gap inputs when needed. 3. Select Exit 1 and Exit 2. 4. The sheet calculates each leg and reconciles Total P&L automatically. | S8: WORKFLOW 1. Enter trade details and original levels. 2. Enter requested 2-day / 4-day or gap inputs when needed. 3. Select Exit 1 and Exit 2. 4. The sheet calculates each leg and reconciles Total P&L automatically. | T8: WORKFLOW 1. Enter trade details and original levels. 2. Enter requested 2-day / 4-day or gap inputs when needed. 3. Select Exit 1 and Exit 2. 4. The sheet calculates each leg and reconciles Total P&L automatically. | U8: WORKFLOW 1. Enter trade details and original levels. 2. Enter requested 2-day / 4-day or gap inputs when needed. 3. Select Exit 1 and Exit 2. 4. The sheet calculates each leg and reconciles Total P&L automatically. | V8: WORKFLOW 1. Enter trade details and original levels. 2. Enter requested 2-day / 4-day or gap inputs when needed. 3. Select Exit 1 and Exit 2. 4. The sheet calculates each leg and reconciles Total P&L automatically. | W8: WORKFLOW 1. Enter trade details and original levels. 2. Enter requested 2-day / 4-day or gap inputs when needed. 3. Select Exit 1 and Exit 2. 4. The sheet calculates each leg and reconciles Total P&L automatically. | X8: WORKFLOW 1. Enter trade details and original levels. 2. Enter requested 2-day / 4-day or gap inputs when needed. 3. Select Exit 1 and Exit 2. 4. The sheet calculates each leg and reconciles Total P&L automatically. | Y8: WORKFLOW 1. Enter trade details and original levels. 2. Enter requested 2-day / 4-day or gap inputs when needed. 3. Select Exit 1 and Exit 2. 4. The sheet calculates each leg and reconciles Total P&L automatically. | Z8: WORKFLOW 1. Enter trade details and original levels. 2. Enter requested 2-day / 4-day or gap inputs when needed. 3. Select Exit 1 and Exit 2. 4. The sheet calculates each leg and reconciles Total P&L automatically.
A9: Lot Size | C9: 1 | F9: Return % | H9: =IF(OR(H7="",H7<=0),"",H8/H7) -> 0.17529342 | J9: Win Rate | L9: =IF(H10=0,"",L7/H10) -> 1 | N9: WORKFLOW 1. Enter trade details and original levels. 2. Enter requested 2-day / 4-day or gap inputs when needed. 3. Select Exit 1 and Exit 2. 4. The sheet calculates each leg and reconciles Total P&L automatically. | O9: WORKFLOW 1. Enter trade details and original levels. 2. Enter requested 2-day / 4-day or gap inputs when needed. 3. Select Exit 1 and Exit 2. 4. The sheet calculates each leg and reconciles Total P&L automatically. | P9: WORKFLOW 1. Enter trade details and original levels. 2. Enter requested 2-day / 4-day or gap inputs when needed. 3. Select Exit 1 and Exit 2. 4. The sheet calculates each leg and reconciles Total P&L automatically. | Q9: WORKFLOW 1. Enter trade details and original levels. 2. Enter requested 2-day / 4-day or gap inputs when needed. 3. Select Exit 1 and Exit 2. 4. The sheet calculates each leg and reconciles Total P&L automatically. | R9: WORKFLOW 1. Enter trade details and original levels. 2. Enter requested 2-day / 4-day or gap inputs when needed. 3. Select Exit 1 and Exit 2. 4. The sheet calculates each leg and reconciles Total P&L automatically. | S9: WORKFLOW 1. Enter trade details and original levels. 2. Enter requested 2-day / 4-day or gap inputs when needed. 3. Select Exit 1 and Exit 2. 4. The sheet calculates each leg and reconciles Total P&L automatically. | T9: WORKFLOW 1. Enter trade details and original levels. 2. Enter requested 2-day / 4-day or gap inputs when needed. 3. Select Exit 1 and Exit 2. 4. The sheet calculates each leg and reconciles Total P&L automatically. | U9: WORKFLOW 1. Enter trade details and original levels. 2. Enter requested 2-day / 4-day or gap inputs when needed. 3. Select Exit 1 and Exit 2. 4. The sheet calculates each leg and reconciles Total P&L automatically. | V9: WORKFLOW 1. Enter trade details and original levels. 2. Enter requested 2-day / 4-day or gap inputs when needed. 3. Select Exit 1 and Exit 2. 4. The sheet calculates each leg and reconciles Total P&L automatically. | W9: WORKFLOW 1. Enter trade details and original levels. 2. Enter requested 2-day / 4-day or gap inputs when needed. 3. Select Exit 1 and Exit 2. 4. The sheet calculates each leg and reconciles Total P&L automatically. | X9: WORKFLOW 1. Enter trade details and original levels. 2. Enter requested 2-day / 4-day or gap inputs when needed. 3. Select Exit 1 and Exit 2. 4. The sheet calculates each leg and reconciles Total P&L automatically. | Y9: WORKFLOW 1. Enter trade details and original levels. 2. Enter requested 2-day / 4-day or gap inputs when needed. 3. Select Exit 1 and Exit 2. 4. The sheet calculates each leg and reconciles Total P&L automatically. | Z9: WORKFLOW 1. Enter trade details and original levels. 2. Enter requested 2-day / 4-day or gap inputs when needed. 3. Select Exit 1 and Exit 2. 4. The sheet calculates each leg and reconciles Total P&L automatically.
F10: Completed Trades | H10: =COUNT(Y14:Y213) -> 2 | J10: Open / Incomplete | L10: =MAX(0,COUNTA(D14:D213)-H10) -> 1
A12: TRADE DETAILS | B12: TRADE DETAILS | C12: TRADE DETAILS | D12: TRADE DETAILS | E12: TRADE DETAILS | F12: TRADE DETAILS | G12: TRADE DETAILS | H12: TRADE DETAILS | I12: STOP-LOSS RECALCULATION | J12: STOP-LOSS RECALCULATION | K12: STOP-LOSS RECALCULATION | L12: STOP-LOSS RECALCULATION | M12: STOP-LOSS RECALCULATION | N12: STOP-LOSS RECALCULATION | O12: STOP-LOSS RECALCULATION | P12: STOP-LOSS RECALCULATION | Q12: STOP-LOSS RECALCULATION | R12: STOP-LOSS RECALCULATION | S12: STOP-LOSS RECALCULATION | T12: STOP-LOSS RECALCULATION | U12: EXIT RESULTS | V12: EXIT RESULTS | W12: EXIT RESULTS | X12: EXIT RESULTS | Y12: FINAL RESULT | Z12: FINAL RESULT
A13: S.No | B13: Date | C13: Contract | D13: Trade Buy or Sell | E13: Entry | F13: Target | G13: Stoploss 1 | H13: Stoploss 2 | I13: SL1 Required Input | J13: SL1 Recalculation Input | K13: Stoploss 1 Recalculation | L13: SL2 Required Input | M13: SL2 Recalculation Input | N13: Stoploss 2 Recalculation | O13: Gap SL1 Required Input | P13: Gap SL1 Input | Q13: Gap Stoploss 1 Calculation | R13: Gap SL2 Required Input | S13: Gap SL2 Input | T13: Gap Stoploss 2 Calculation | U13: Exit 1 Selection | V13: Exit 1 Profit & Loss | W13: Exit 2 Selection | X13: Exit 2 Profit & Loss | Y13: Total P&L | Z13: Rollover Price
A14: 1 | B14: 46239 | C14: SEP | D14: Buy | E14: 145964.95 | F14: 148154.42 | G14: 143775.47 | H14: 143775.47 | I14: =IF(D14="Buy","Enter New 2DLL",IF(D14="Sell","Enter New 2DHH","")) -> Enter New 2DLL | K14: =IF(OR(D14="",E14=""),"",IF(J14="",G14,IF(D14="Buy",MROUND(MAX(E14*(1-Settings!$K$8),J14*(1-Settings!$K$6)),Settings!$K$10),MROUND(MIN(E14*(1+Settings!$K$8),J14*(1+Settings!$K$6)),Settings!$K$10)))) -> 143775.47 | L14: =IF(D14="Buy","Enter New 4DLL",IF(D14="Sell","Enter New 4DHH","")) -> Enter New 4DLL | M14: 159112 | N14: =IF(OR(D14="",E14=""),"",IF(M14="",H14,IF(D14="Buy",MROUND(MAX(E14*(1-Settings!$K$8),M14*(1-Settings!$K$6)),Settings!$K$10),MROUND(MIN(E14*(1+Settings!$K$8),M14*(1+Settings!$K$6)),Settings!$K$10)))) -> 158921 | O14: =IF(D14="Buy","Enter First 15-Minute Low",IF(D14="Sell","Enter First 15-Minute High","")) -> Enter First 15-Minute Low | Q14: =IF(OR(D14="",P14=""),"",IF(D14="Buy",MROUND(P14*(1-Settings!$K$6),Settings!$K$10),MROUND(P14*(1+Settings!$K$6),Settings!$K$10))) | R14: =IF(D14="Buy","Enter First 15-Minute Low",IF(D14="Sell","Enter First 15-Minute High","")) -> Enter First 15-Minute Low | T14: =IF(OR(D14="",S14=""),"",IF(D14="Buy",MROUND(S14*(1-Settings!$K$6),Settings!$K$10),MROUND(S14*(1+Settings!$K$6),Settings!$K$10))) | U14: Target Hit | V14: =IF(OR(D14="",E14="",U14="",$C$8="",$C$9=""),"",IF(U14="Target Hit",IF(F14="","",IF(D14="Buy",(F14-E14)*($C$8/2)*$C$9,(E14-F14)*($C$8/2)*$C$9)),IF(U14="Rollover",IF(Z14="","",IF(D14="Buy",(Z14-E14)*$C$8*$C$9,(E14-Z14)*$C$8*$C$9)),IF(U14="Stoploss 1 Hit",IF(K14="","",IF(D14="Buy",(K14-E14)*$C$8*$C$9,(E14-K14)*$C$8*$C$9)),IF(OR(AND(D14="Buy",U14="Gap Down Stoploss 1 Hit"),AND(D14="Sell",U14="Gap Up Stoploss 1 Hit")),IF(Q14="","",IF(D14="Buy",(Q14-E14)*$C$8*$C$9,(E14-Q14)*$C$8*$C$9)),""))))) -> 2189.4742 | W14: Stoploss 2 Hit | X14: =IF(OR(D14="",E14="",U14<>"Target Hit",W14="",$C$8="",$C$9=""),"",IF(W14="Stoploss 2 Hit",IF(N14="","",IF(D14="Buy",(N14-E14)*($C$8/2)*$C$9,(E14-N14)*($C$8/2)*$C$9)),IF(W14="Rollover",IF(Z14="","",IF(D14="Buy",(Z14-E14)*($C$8/2)*$C$9,(E14-Z14)*($C$8/2)*$C$9)),IF(OR(AND(D14="Buy",W14="Gap Down Stoploss 2 Hit"),AND(D14="Sell",W14="Gap Up Stoploss 2 Hit")),IF(T14="","",IF(D14="Buy",(T14-E14)*($C$8/2)*$C$9,(E14-T14)*($C$8/2)*$C$9)),"")))) -> 12956.052 | Y14: =IF(AND(V14="",X14=""),"",SUM(V14,X14)) -> 15145.526 | Z14: 146965
A15: 2 | B15: 46261 | C15: SEP | D15: Sell | E15: 158921.07 | F15: 156537.25 | G15: 161304.88 | H15: 161304.88 | I15: =IF(D15="Buy","Enter New 2DLL",IF(D15="Sell","Enter New 2DHH","")) -> Enter New 2DHH | K15: =IF(OR(D15="",E15=""),"",IF(J15="",G15,IF(D15="Buy",MROUND(MAX(E15*(1-Settings!$K$8),J15*(1-Settings!$K$6)),Settings!$K$10),MROUND(MIN(E15*(1+Settings!$K$8),J15*(1+Settings!$K$6)),Settings!$K$10)))) -> 161304.88 | L15: =IF(D15="Buy","Enter New 4DLL",IF(D15="Sell","Enter New 4DHH","")) -> Enter New 4DHH | M15: 154148 | N15: =IF(OR(D15="",E15=""),"",IF(M15="",H15,IF(D15="Buy",MROUND(MAX(E15*(1-Settings!$K$8),M15*(1-Settings!$K$6)),Settings!$K$10),MROUND(MIN(E15*(1+Settings!$K$8),M15*(1+Settings!$K$6)),Settings!$K$10)))) -> 154333 | O15: =IF(D15="Buy","Enter First 15-Minute Low",IF(D15="Sell","Enter First 15-Minute High","")) -> Enter First 15-Minute High | Q15: =IF(OR(D15="",P15=""),"",IF(D15="Buy",MROUND(P15*(1-Settings!$K$6),Settings!$K$10),MROUND(P15*(1+Settings!$K$6),Settings!$K$10))) | R15: =IF(D15="Buy","Enter First 15-Minute Low",IF(D15="Sell","Enter First 15-Minute High","")) -> Enter First 15-Minute High | T15: =IF(OR(D15="",S15=""),"",IF(D15="Buy",MROUND(S15*(1-Settings!$K$6),Settings!$K$10),MROUND(S15*(1+Settings!$K$6),Settings!$K$10))) | U15: Target Hit | V15: =IF(OR(D15="",E15="",U15="",$C$8="",$C$9=""),"",IF(U15="Target Hit",IF(F15="","",IF(D15="Buy",(F15-E15)*($C$8/2)*$C$9,(E15-F15)*($C$8/2)*$C$9)),IF(U15="Rollover",IF(Z15="","",IF(D15="Buy",(Z15-E15)*$C$8*$C$9,(E15-Z15)*$C$8*$C$9)),IF(U15="Stoploss 1 Hit",IF(K15="","",IF(D15="Buy",(K15-E15)*$C$8*$C$9,(E15-K15)*$C$8*$C$9)),IF(OR(AND(D15="Buy",U15="Gap Down Stoploss 1 Hit"),AND(D15="Sell",U15="Gap Up Stoploss 1 Hit")),IF(Q15="","",IF(D15="Buy",(Q15-E15)*$C$8*$C$9,(E15-Q15)*$C$8*$C$9)),""))))) -> 2383.816 | X15: =IF(OR(D15="",E15="",U15<>"Target Hit",W15="",$C$8="",$C$9=""),"",IF(W15="Stoploss 2 Hit",IF(N15="","",IF(D15="Buy",(N15-E15)*($C$8/2)*$C$9,(E15-N15)*($C$8/2)*$C$9)),IF(W15="Rollover",IF(Z15="","",IF(D15="Buy",(Z15-E15)*($C$8/2)*$C$9,(E15-Z15)*($C$8/2)*$C$9)),IF(OR(AND(D15="Buy",W15="Gap Down Stoploss 2 Hit"),AND(D15="Sell",W15="Gap Up Stoploss 2 Hit")),IF(T15="","",IF(D15="Buy",(T15-E15)*($C$8/2)*$C$9,(E15-T15)*($C$8/2)*$C$9)),"")))) | Y15: =IF(AND(V15="",X15=""),"",SUM(V15,X15)) -> 2383.816
